Workbook

Sheet Start Here
A1: Start Here — Future Turtles 2026 Drinks, orientation for whoever builds the menu
A3: A free bar at Burning Man 2026. Non-alcoholic 'dirty sodas' built to order, with an optional shot for anyone who wants one. No money changes hands. THE WORKBOOK IS FINISHED AS A PLAN — what is wanted next is two pieces of design: (1) a guest-facing MENU, and (2) BARTENDER INSTRUCTIONS for people who have never made these drinks and will be reading in the dark, dusty and probably impaired.
A6: THE SHAPE OF IT
A7: Roughly 1,460 servings across 8 days — Sunday through the closing Sunday, with that last one a daytime cafe rather than a night. 16 built-to-order recipes available all week (including Root Access, the dirty root beer float, and the two tequila builds below), 3 Saturday-only reveals, one 33-serving jug special per service, and Turtle Soup on its own standalone sign. THE JUG CHANGES EVERY DAY EXCEPT ONE: Saturday and the closing Sunday pour the same peach green iced tea, deliberately, so that the busiest night of the week has one thing on it that needs no attention. TWO DRINKS BREAK THE LIQUOR-IS-OPTIONAL RULE — Rawhide and Localhost are tequila builds, sized at 100% uptake (Assumptions B222); both have non-alcoholic versions from stock on hand, and Rawhide’s is already on the standing board as salted soda water + lime. *** AS OF 11 Aug 2026 NEITHER PRINTS IN A BLOCK THAT SAYS SO: *** the old tequila-builds block is gone, Localhost sits among the built drinks and Rawhide in LESS SWEET, but both are still costed at a full shot on every serving. If you are designing the menu, the tequila needs to be visible on those two lines — the liquor column says 'IN THE BUILD, not optional' for exactly that reason. On top of that, 128 servings are cold cans a camper takes from the cooler with no bartender involved — Red Bull, coconut water and the Grapefruit Radler. Live figure for total servings is ‘Totals by Type’ B12.
A9: TABS YOU NEED FOR DESIGN
A10: 'Service Availability' — START HERE. What is on offer and when. Three groups: all-week, Saturday-only, and the nightly jug. This is the tab that decides the menu's structure. 'Dirty Soda - Built Drinks' — the build spec for every drink: base, per-serving oz of each ingredient, garnish, and the optional liquor. This is where bartender instructions come from. (Older notes across the workbook call this tab 'Recipes'; same tab, it was renamed.) 'Jug Recipes' — the nightly jug specials, one per night, with their own ingredients. 'Bar Add-Ons' — no-prep items a bartender hands over or splashes in. Free menu extensions, and where the LESS SWEET items are costed. 'Menu Board' — the existing rough board layout, live-linked to the names. THE 'LESS SWEET' BLOCK IS THE ONE TO GIVE REAL SPACE TO — it is the answer to 'have you got anything not too sweet?', which is the question this bar gets most often by Wednesday.
A12: TABS THAT ARE PROCUREMENT ONLY — IGNORE FOR DESIGN
A13: 'Purchase List', 'Packaged Sizing', 'Packaged Prices', 'Ingredient Pricing', 'Assumptions', 'Other Consumables', 'Base Soda — Cans', 'Beverage Lines', 'Totals by Type', 'Camp Drinks', 'Supplies'. These size and cost the shopping trip. Nothing in them belongs on a menu.
A15: HOUSE CONVENTIONS
A16: Standard pour is 8 oz over ice — small on purpose, so people can try several and nothing gets abandoned half-drunk. Liquor is always optional and always a 1.5 oz shot; the model assumes 35% of drinks get one. Six liquors behind the bar: vodka, coconut rum, bourbon, blanco tequila, spiced rum, whiskey. Several drinks take a Tajin rim. Cans of beer, cider, Red Bull and coconut water are handed over sealed, not poured.
A18: HARD RULES — DO NOT DESIGN AROUND THESE
A19: The three Saturday reveals (Sakura Kisses, Catboy Snot, Catboy Piss) MUST NOT appear on any menu shown before Saturday. They need their own separate card. Turtle Soup is NOT one of them — it is a standalone sign with no day attached, see 'Service Availability' section 4.
... A26: This plan originally ran on 8 kegs across two tap lines, which is why some tabs still carry keg vocabulary as a costing baseline. That is gone: everything is now bottles and cans on ice, which saved ~$870 and removed the jockey box, CO2 and deposits. The practical consequence for the menu is that the old day-by-day rotation is dead — almost everything is available all week. 'Beverage Lines' and the 'old keg $' columns are historical reference only.

Sheet Dirty Soda - Built Drinks
A1: Drink Recipes — absolute drink counts (per-serving oz)
A2: Recipe | B2: Servings | C2: (share) | D2: Base soda | E2: Base oz | F2: Syrup A | G2: A oz | H2: Syrup B | I2: B oz | J2: Soda water oz | K2: Coconut cream oz | L2: Special / garnish | M2: Liquor (optional) | N2: Liquor oz needed | O2: Tested?
A3: Tang Dynasty | B3: 30 | C3: =B3/$B$24 | D3: Kombucha (Island Mango) | E3: 4 | F3: Tangerine juice | G3: 2 | H3: Passion fruit purée | I3: 0.75 | J3: 0 | K3: 0 | L3: ISLAND MANGO KOMBUCHA as of 14 Aug 2026 — was passionfruit, which is not in the Brew Dr. variety pack. The passion fruit purée is still in the build, so the flavour is still there; mango + tangerine + purée reads rounder and slightly less sharp. Kombucha + tangerine + passion fruit over ice, fresh lime squeeze (Assumptions B113), slapped mint or basil leaf; stir. | M3: Vodka | N3: =B3*Assumptions!$B$39*Assumptions!$B$40 | O3: Yes
A4: Michelada | B4: =Assumptions!$B$60 | C4: =B4/$B$24 | D4: Mexican Lager | E4: 6 | F4: Tres Agaves Bloody Mary Mix | G4: 2.5 | H4: Lime juice (fresh) | I4: 0.5 | J4: 0 | K4: 0 | L4: Chelada built to order off the Mexican Lager keg: 2.5 oz Tres Agaves Bloody Mary Mix + fresh lime + Tajin rim. SWAPPED OFF CLAMATO + HOT SAUCE 18 Aug 2026 — the Bloody Mary mix (tomato, lime, chili pepper, onion, garlic, organic spices) already carries its own spice, so the separate hot sauce dash is dropped; lime squeeze stays. NOTE: this trades away the briny clam-broth character that's traditionally what makes a Michelada a Michelada — it reads more like a straight spicy tomato beer cocktail now, closer to a chelada preparada than an authentic michelada. Flavor call, not a math problem; revert Syrup A to 'Clamato' at 3 oz + restore Assumptions B105 to 0.25 if that's not the direction you want. Extras itemized on Other Consumables rows 39-42. OPTIONAL PREP, ADDED 18 Aug 2026 — PREFERRED IF ON HAND: if tomato juice / V8 turns up on the Reno grocery run (Purchase List row 100), build it as 1 oz Tres Agaves Bloody Mary Mix + 3 oz tomato/V8 juice instead of the default 2.5 oz Bloody Mary Mix alone — less clammy, closer to a straight tomato michelada. NOT SCALED INTO THE BUY: this is bartender's-choice per cup depending on what's in the cooler that day, not a guaranteed swap, so the Bloody Mary Mix purchase quantity (row 23) still assumes the 2.5 oz default for all 30 servings. Practical consequence: if V8 shows up and gets used often, the Bloody Mary Mix draw per serving drops from 2.5 oz to 1 oz, so the 4 bottles already on order will stretch considerably further than planned — that's headroom, not a shortfall. | N4: 0
A5: Vanilla Cherry Grove | B5: 130 | C5: =B5/$B$24 | D5: Coke | E5: 4 | F5: Vanilla | G5: 0.25 | H5: Cherry | I5: 0.25 | J5: 2 | K5: 0 | L5: DOSED DOWN 21 Aug 2026 (back-propagated from the bar guide) — vanilla and cherry cut from 2 pumps (0.5oz) to 1 pump (0.25oz) each, soda water raised 0.5oz to 2oz. Lighter syrup, longer pour. | M5: Bourbon | N5: =B5*Assumptions!$B$39*Assumptions!$B$40 | O5: yes
A6: Orange Cream-sicle | B6: 50 | C6: =B6/$B$24 | D6: Orange Fanta | E6: 4 | G6: 0 | I6: 0 | J6: 1 | K6: 1 | M6: Vodka | N6: =B6*Assumptions!$B$39*Assumptions!$B$40
A7: Watermelon Sugar High | B7: 50 | C7: =B7/$B$24 | D7: Lemonade | E7: 4 | F7: Watermelon juice | G7: 2 | I7: 0 | J7: 1 | K7: 0 | L7: Muddled fresh mint. WATERMELON JUICE COMES OUT OF A CARTON — 2 oz per cup, bought as its own line (Purchase List row 88). It is NOT the whole melons: those are for Monday’s Hard Reset fresca and nothing else, and they are gone by Tuesday. Nothing to blend and nothing to strain here — pour the lemonade, add the juice, muddle the mint, done. This replaced 1 oz of watermelon Torani: real juice at 2 oz reads as fruit rather than as sweetener, and the lemonade is already carrying the sugar. | M7: Blanco Tequila | N7: =B7*Assumptions!$B$39*Assumptions!$B$40
A8: A Ginger's Pickle (Big Dill Energy) | B8: 30 | C8: =B8/$B$24 | D8: Ginger ale | E8: 4 | F8: Pickle Juice | G8: 1 | I8: 0 | J8: 1 | K8: 0 | L8: Ginger ale + 1 oz pickle juice over ice, TAJIN RIM. Pickle juice is a real ingredient in the Syrup A slot as of 10 Aug 2026 (it was 0.5 oz buried in this note, where nothing could add it up) — it doubles the brine draw on 'Other Consumables' row 50. Spears come free with the jars; hand one over if asked. | M8: Whiskey | N8: =B8*Assumptions!$B$39*Assumptions!$B$40
A9: The Dr's Cream | B9: 40 | C9: =B9/$B$24 | D9: Dr Pepper | E9: 4 | F9: Vanilla | G9: 0.5 | I9: 0 | J9: 1 | K9: 0.5 | L9: DOSED DOWN 21 Aug 2026 (back-propagated from the bar guide) — vanilla cut from 1oz to 0.5oz (2 pumps), same pump-to-oz convention as the rest of the syrup builds. | M9: Bourbon | N9: =B9*Assumptions!$B$39*Assumptions!$B$40 | O9: yes
A10: The Dr's Peach Exam | B10: 40 | C10: =B10/$B$24 | D10: Dr Pepper | E10: 4 | F10: Vanilla | G10: 0.25 | H10: Peach | I10: 0.25 | J10: 1 | K10: 0.5 | L10: Dr Pepper + vanilla syrup + peach syrup + coconut cream, over ice. DOSED DOWN 20 Aug 2026 — vanilla and peach both cut from 2 pumps (0.5 oz) to 1 pump (0.25 oz, Assumptions B8a) each. Two full pumps of both flavors together was heavy-handed; one pump each still reads as a peach-vanilla Dr Pepper, just lighter, and stretches the tighter peach stock further. | M10: Whiskey | N10: =B10*Assumptions!$B$39*Assumptions!$B$40 | O10: yes
A11: SCOBY Mule | B11: 20 | C11: =B11/$B$24 | D11: Kombucha (Superberry) | E11: 4 | F11: Yuzu juice | G11: 0.5 | H11: Ginger beer | I11: 3 | J11: 0 | K11: 0 | L11: SUPERBERRY KOMBUCHA as of 14 Aug 2026. *** ANY FLAVOUR WORKS IF SUPERBERRY IS OUT — this build has always been spec’d "either", and berry is a preference, not a requirement. Substitute Island Mango or Clear Mind without asking anyone. *** Berry against the ginger and yuzu is the best of the three, and it is also the flavour with the most slack in the buy (see Packaged Sizing section 7). Kombucha over ice + 0.5 oz YUZU JUICE + agave + apple cider vinegar, topped with ginger beer. The moscow-mule shape: sharp, gingery, not sweet. Per-serving agave and ACV are on Assumptions B131/B128. YUZU REPLACED THE FRESH LEMON 10 Aug 2026, following Clear Cache — with both builds moved there is no fresh lemon left anywhere on the bar and nothing to juice but limes. Yuzu is bottled and shelf-stable, so it is a pour, not a prep job. Jigger it: at $1.54/oz it is the dearest thing behind the bar. *** ASK IF THEY WANT IT DIRTY (ADD DEW). *** A splash of Mountain Dew is the standing modifier on the kombucha builds as of 11 Aug 2026, replacing SCOBY-Dew as a named drink. It is an offer, not a default: ask, do not assume. | M11: Vodka | N11: =B11*Assumptions!$B$39*Assumptions!$B$40
A12: Thirst Trap | B12: 50 | C12: =B12/$B$24 | D12: Squirt | E12: 4 | F12: Peach | G12: 0.25 | H12: Lime juice (fresh) | I12: 0.5 | J12: 1 | K12: 0 | L12: Squirt + peach syrup + fresh lime over ice. DOSED DOWN 20 Aug 2026 — peach cut from 3 pumps (0.75 oz) to 1 pump (0.25 oz); Squirt already carries plenty of its own fruit character, peach was rounding it more than necessary. MINT CUBE IF AVAILABLE — cubes are not guaranteed, the drink is complete without one, so never hold a build waiting for one. Two-finger pinch of salt or a Tajin rim: the salt is what kills the grapefruit bitterness, and peach only softens it. Replaced Thirst Trap, where Squirt fought muddled cucumber and the soda water thinned what was left — peach rounds the grapefruit instead of competing with it. No muddling, so it is a fast build. | M12: Blanco Tequila | N12: =B12*Assumptions!$B$39*Assumptions!$B$40
A13: Sakura Kisses | B13: 33 | C13: =B13/$B$24 | D13: Green tea | E13: 4 | F13: Orange syrup | G13: 0.5 | H13: Sakura syrup | I13: 0.5 | J13: 0 | K13: 0 | L13: SATURDAY ONLY — Catboy Café finale, built to order off the green tea keg (replaces the retired Saturday aqua fresca jug). Green tea over ice + sakura syrup + orange syrup (0.5 oz each), plus passion fruit purée (Assumptions B118); mint or cucumber garnish. CHANGED 21 Aug 2026 — dropped the 2 oz orange juice pour; orange syrup now carries the orange note at 0.5 oz instead. | N13: 0
A14: Clear Cache | B14: 30 | C14: =B14/$B$24 | D14: Kombucha (Clear Mind) | E14: 4 | F14: Peach | G14: 0.25 | H14: Yuzu juice | I14: 0.5 | J14: 2 | K14: 0 | L14: Built off Dr. Clear Mind kombucha (rosemary, mint, sage, green tea). Kombucha over ice + peach syrup (DOSED DOWN 20 Aug 2026, 2 pumps/0.5 oz to 1 pump/0.25 oz — the kombucha and sage already carry most of the flavor, peach was a background note anyway) + 0.5 oz YUZU JUICE, topped with soda water. Rub a sage leaf around the cup rim and drop it in; optional pinch of salt. YUZU REPLACED THE FRESH LEMON 10 Aug 2026 — floral and more bitter-aromatic than lemon, which suits the rosemary-sage kombucha. It is bottled, so there is nothing to squeeze and nothing to keep cold. | M14: Bourbon | N14: =B14*Assumptions!$B$39*Assumptions!$B$40 | O14: yes
A15: Catboy Snot | B15: 25 | C15: =B15/$B$24 | D15: Squirt | E15: 4 | F15: Melon | G15: 0.5 | H15: Lime juice (fresh) | I15: 0.5 | J15: 0 | K15: 0 | L15: SATURDAY ONLY — Catboy Café finale, do not put it on the board before Saturday. Squirt + melon syrup + fresh lime over ice, then 1.5 oz of aloe vera juice WITH THE PULP spooned in (per-serving oz on Assumptions B147) so the cubes hang in suspension — that is the whole gag. Two-finger pinch of salt, same as Thirst Trap: the salt is what kills the grapefruit bitterness. Tint the ALOE BOTTLE (not the cup) with a pinch of blue spirulina — pale-yellow Squirt + blue reads green, and tinting per-cup comes out uneven. THE SPIRULINA JAR IS NOW BOUGHT FOR THIS ONE JOB (Purchase List row 52): Blue Screen of Death is retired, so nothing else in the workbook uses it. A pinch does it; the jar is ample. Optional basil seeds (Assumptions B150), hydrated in water ahead of service. BUY DRINKING ALOE — inner-fillet/decolorized, NOT whole-leaf or supplement aloe (aloin = laxative). | M15: Blanco Tequila | N15: =B15*Assumptions!$B$39*Assumptions!$B$40
A16: Catboy Piss | B16: 25 | C16: =B16/$B$24 | D16: Red Bull (Yellow Edition) | E16: 4 | F16: Passion fruit purée | G16: 0.5 | H16: Lime juice (fresh) | I16: 0.5 | J16: 0 | K16: 0 | L16: SATURDAY ONLY — do not put it on the board before Saturday. YELLOW EDITION RED BULL, NOT REGULAR (specified 14 Aug 2026): the drink is named for its colour, and the passion fruit purée only reads as an alarming gold off a yellow base — regular Red Bull is amber and goes muddy brown. Yellow Edition is tropical, so the passion fruit adds to it instead of fighting it. Red Bull + blanco tequila over ice, passion fruit purée and fresh lime, Tajin rim. The purée deepens the colour and its tartness cuts the Red Bull sweetness; the salty-spicy rim is what stops it tasting like a dorm drink. Red Bull comes off the Bar Add-Ons tab (12 of the 24 YELLOW cans). SATURDAY COLOUR SET: this is the yellow one — Sakura Kisses is pink and Catboy Snot is green. Keep all three distinct. | M16: Blanco Tequila | N16: =B16*Assumptions!$B$39*Assumptions!$B$40
A17: Shirley Temple of Doom | B17: 25 | C17: =B17/$B$24 | D17: Sprite | E17: 4 | F17: Cherry | G17: 0.5 | H17: Lime juice (fresh) | I17: 0.5 | J17: 2 | K17: 0 | L17: Sprite + cherry syrup (DOSED DOWN 21 Aug 2026, back-propagated from the bar guide — 3 pumps/0.75oz to 2 pumps/0.5oz) + fresh lime over ice, topped with soda water. TAJIN RIM plus a two-finger pinch of salt — cherry + chile-lime is chamoy logic, and the salt and acid are what stop it reading as candy in the heat. Same rim station as the Michelada, A Ginger's Pickle and Catboy Piss, so it adds no new workflow. No coconut cream (it was pulled from the plain Shirley Temple on row 6 as well). | M17: Vodka | N17: =B17*Assumptions!$B$39*Assumptions!$B$40 | O17: yes
A18: Shirley Mule | B18: 25 | C18: =B18/$B$24 | D18: Sprite | E18: 2 | F18: Cherry | G18: 0.75 | H18: Ginger beer | I18: 3 | J18: 0 | K18: 0 | L18: Sprite + ginger beer + cherry syrup over ice, plus a 0.5 oz fresh lime squeeze (Assumptions B154 — the two ingredient slots here are full, same situation as Tang Dynasty). BASE SWAPPED TO SPRITE 10 Aug 2026 and ginger beer raised from 2 to 3 oz: the ginger now comes entirely from the ginger beer instead of being split with ginger ale, and the pour volume is unchanged at 6.25 oz. Ginger is genuinely useful for dust-and-heat stomach and the ginger beer's bite cuts the cherry. Vodka is the default; whiskey works if someone asks. | M18: Vodka | N18: =B18*Assumptions!$B$39*Assumptions!$B$40 | O18: yes
A19: Root Access | B19: 40 | C19: =B19/$B$24 | D19: Root beer | E19: 4 | F19: Vanilla | G19: 0.5 | I19: 0 | J19: 2 | K19: 1 | L19: A dirty root beer float. 4 oz root beer + 0.5 oz vanilla syrup + 1 oz cream of coconut over ice — stir gently, it will foam. Cream of coconut instead of dairy means it will not curdle and needs no refrigeration once opened. Cherry syrup in place of vanilla is the other good build. | M19: Spiced Rum | N19: =B19*Assumptions!$B$39*Assumptions!$B$40 | O19: yes
A20: Paloma | B20: 20 | C20: =B20/$B$24 | D20: Paloma mixer | E20: 3 | J20: 5 | K20: 0 | L20: NEW 18 Aug 2026. SALT RIM. 3 oz paloma mixer + 5 oz soda water over ice, lime wedge. Optional 1.5 oz blanco tequila OR vodka — tequila is the paloma, vodka is the cleaner one and both work. Complete and good without either, sized at the standard 35% uptake like its sibling Guavascript, not the 100% the two tequila-mandatory builds use. The mixer already carries grapefruit, lime and agave, so nothing else is added by default. OPTIONAL ENHANCEMENT: a splash of watermelon juice or extra fresh lime on request — not scaled into the buy, both are already stocked for other drinks, so pouring a little into this one costs nothing extra to plan for. SPICY OPTION: 2-3 drops of Fee Brothers Habanero Bitters on request — ask before adding, it's a real kick, not a suggestion of heat. | M20: Blanco Tequila | N20: =B20*Assumptions!$B$39*Assumptions!$B$40 | O20: No — NEW, untested
A21: Ranch Water | B21: 20 | C21: =B21/$B$24 | E21: 0 | F21: Lime juice (fresh) | G21: 0.5 | I21: 0 | J21: 6 | K21: 0 | L21: SALT RIM, then 1.5 oz blanco tequila + 0.5 oz FRESH lime + 6 oz soda water over ice. Nothing else — no syrup, no sugar, no colour. SODA WATER CUT 8 oz TO 6 ON 11 Aug 2026, which brings the drink to exactly the 8 oz house pour instead of 10 and takes 40 oz off the soda water buy. It is a tighter, less watery ranch water for it. THIS IS THE "HAVE YOU GOT ANYTHING NOT TOO SWEET?" DRINK: the only genuinely dry thing on the board, and after four days of syrup that question gets asked a lot. The non-alcoholic version is on the standing board as salted soda water + lime. | M21: Blanco Tequila | N21: =B21*Assumptions!$B$222*Assumptions!$B$40
A22: Margarita | B22: 20 | C22: =B22/$B$24 | D22: Margarita mixer | E22: 4 | G22: 0 | H22: Fresh lime | I22: 1 | J22: 0 | K22: 0 | L22: SALT RIM. 4 oz margarita mixer + 1.5 oz blanco tequila over ice, then 1 oz FRESH lime and 0.5 oz agave (Assumptions B224) TO TASTE. THE LIME AND THE AGAVE ARE OPTIONAL — the mixer already contains both; start with mixer + tequila, taste, and add only if it needs it. Both stay fully costed and are bought for other drinks anyway, so leaving them out wastes nothing. *** HIBISCUS REMOVED 11 Aug 2026 — THIS IS NOW A STANDARD MARGARITA. *** It was a hibiscus margarita built on cold-steeped flower, which meant the drink could not be poured unless someone had steeped a batch the night before. With hibiscus now also feeding the Daily Tea standing tea, that prep was competing with itself. 4 oz of mixer to 1.5 oz of tequila is the mixer's own ratio. *** THE TEQUILA IS NOT OPTIONAL HERE. *** A margarita without it is not this drink — it is sized at 100% uptake on Assumptions B222, unlike every other built drink, which sizes at 35% on B39. If someone wants it dry, pour them an Iced Tea or a Bitwise instead of a diluted margarita. | M22: Blanco Tequila | N22: =B22*Assumptions!$B$222*Assumptions!$B$40
A23: Guavascript | B23: 25 | C23: =B23/$B$24 | D23: Paloma mixer | E23: 3 | H23: Guava syrup | I23: 0.5 | J23: 4.5 | K23: 0 | L23: SALT OR TAJIN RIM. 3 oz paloma mixer + 0.5 oz guava syrup + 4.5 oz soda water over ice, lime wedge. SWITCHED FROM GUAVA PUREE TO TORANI GUAVA SYRUP 19 Aug 2026 — Reàl guava purée wasn't at Total Wine and Amazon only sells it in a 3-pack; Torani Guava syrup is the same 750ml/25.4oz format as the other Torani flavors already on the truck, easier to source. Same 0.5 oz dose carried over — syrup is thinner and sweeter than purée, so taste it against the original if you get the chance; the guava character may read a little different (less pulp/body, more straight sweetness) even at the same pour. Optional 1.5 oz blanco tequila OR vodka — tequila is the paloma, vodka is the cleaner one and both work. Complete and good without either, which is why it sizes at the standard 35% uptake rather than the 100% the two tequila builds use. OPTIONAL ENHANCEMENT: a splash of watermelon juice or extra fresh lime on request — not scaled into the buy, both are already stocked for other drinks. CONTINGENCY, 19 Aug 2026: if guava (syrup or purée) doesn't turn up at Total Wine this weekend and Amazon stays unreliable, the fallback is pulling Guavascript from the menu entirely rather than serving it without its one twist ingredient. | M23: Blanco Tequila | N23: =B23*Assumptions!$B$39*Assumptions!$B$40 | O23: No — NEW, untested
A24: TOTAL BUILT-TO-ORDER SERVINGS | B24: =SUM(B3:B23) | N24: =SUM(N3:N23) | O24: Renamed from "dirty soda" — row 21 (Rawhide) is a tequila build with no canned base at all, and rows 22 and 23 carry a bottled mixer in the base slot rather than a soda: Localhost takes 4 oz of margarita mixer as of 11 Aug 2026, Guavascript 3 oz of paloma mixer. All three still roll into the "Dirty soda — canned base" bucket on Totals by Type row 10, which is a slight misnomer for three of the twenty-one. NOTE the base slot is read by "Base Soda — Cans" (which matches on soda names only, so the two mixers fall through harmlessly) AND by "Other Consumables" rows 55 and 57, which is what actually buys them — that is why the mixers sit there rather than in a syrup slot.
A26: SECRET PARTY — off-menu, NOT included in TOTAL BUILT-TO-ORDER SERVINGS (B24). Camp-mate request, 21 Aug 2026. Keep off the standing board and the Menu Board — a separate menu is being built just for this event (Service Availability section 6, Start Here hard rule).
A27: Recipe | B27: Servings | C27: (share) | D27: Base soda | E27: Base oz | F27: Syrup A | G27: A oz | H27: Syrup B | I27: B oz | J27: Soda water oz | K27: Coconut cream oz | L27: Special / garnish | M27: Liquor (optional) | N27: Liquor oz needed | O27: Tested?
A28: Vodka Shot | B28: =Assumptions!$B$286 | C28: =B28/$B$34 | D28: — | L28: SECRET PARTY. Neat or on the rocks — no mixer, no build, fastest possible pour. This is the "I just need it in a cup" option when the line gets long. | M28: Vodka | N28: =B28*Assumptions!$B$277*Assumptions!$B$40 | O28: No — NEW, off-menu
A29: Vodka Cranberry | B29: =Assumptions!$B$287 | C29: =B29/$B$34 | D29: Cranberry juice | E29: =Assumptions!$B$293 | L29: SECRET PARTY. Vodka + cranberry juice over ice. One pour, no muddle — built for a fast line. | M29: Vodka | N29: =B29*Assumptions!$B$277*Assumptions!$B$40 | O29: No — NEW, off-menu
A30: Screwdriver | B30: =Assumptions!$B$288 | C30: =B30/$B$34 | D30: Orange juice | E30: =Assumptions!$B$294 | L30: SECRET PARTY. Vodka + orange juice over ice. | M30: Vodka | N30: =B30*Assumptions!$B$277*Assumptions!$B$40 | O30: No — NEW, off-menu
A31: Vodka Red Bull | B31: =Assumptions!$B$289 | C31: =B31/$B$34 | D31: Red Bull | E31: 4 | L31: SECRET PARTY. Vodka + Red Bull over ice — draws off the Red Bull already stocked for the standing board (Bar Add-Ons), not a new purchase. Either flavor works; save the Yellow Edition for Catboy Piss if both land the same night. | M31: Vodka | N31: =B31*Assumptions!$B$277*Assumptions!$B$40 | O31: No — NEW, off-menu
A32: Vodka Lemonade | B32: =Assumptions!$B$290 | C32: =B32/$B$34 | D32: Lemonade | E32: 4 | L32: SECRET PARTY. Vodka + lemonade over ice — draws off the lemonade already stocked for Watermelon Sugar High, not a new purchase. | M32: Vodka | N32: =B32*Assumptions!$B$277*Assumptions!$B$40 | O32: No — NEW, off-menu
A33: Vodka Soda | B33: =Assumptions!$B$291 | C33: =B33/$B$34 | D33: Soda water | E33: 4 | L33: SECRET PARTY. Vodka + soda water + lime squeeze — draws off soda water already stocked, assumed sufficient for this event (no extra purchase added, per your 21 Aug 2026 call). REPLACED VODKA TONIC 21 Aug 2026. | M33: Vodka | N33: =B33*Assumptions!$B$277*Assumptions!$B$40 | O33: No — NEW, off-menu
A34: TOTAL SECRET PARTY SERVINGS | B34: =SUM(B28:B33) | N34: =SUM(N28:N33)

Sheet Jug Recipes
A1: Jug Recipes — the nightly 10 L batch, and what goes in it
A2: One batch per night. SET THE NUMBER OF JUGS IN COLUMN B — servings and every ingredient quantity scale off it automatically, and the buy quantities at the bottom of this tab follow. Wednesday already runs 3 jugs for the next-door party. Ingredients are listed strongest-first with water/ice fills last, so nothing real hides behind a zero. READ THE NOTES COLUMN: Sunday’s Cherry Bomb is built in two halves, and Thursday’s Fee Brothers Cherry Bitters go into the cup rather than the jug. SATURDAY AND THE CLOSING SUNDAY POUR THE SAME PEACH GREEN ICED TEA — two separate overnight steeps, one started Friday night and one Saturday night. Day-by-day prep is on ‘Daily Schedule’.
A3: Day | B3: # Jugs | C3: Offering | D3: Format | E3: Servings | F3: Ingredient 1 | G3: Ing 1 oz | H3: Ingredient 2 | I3: Ing 2 oz | J3: Ingredient 3 | K3: Ing 3 oz | L3: Ingredient 4 | M3: Ing 4 oz | N3: Ingredient 5 | O3: Ing 5 oz | P3: Alcohol (optional) | Q3: Alcohol — 2nd option (SIGNAGE ONLY) | R3: Alcohol oz needed | S3: Notes
A4: Sunday | B4: 1 | C4: Cherry Bomb (Cherry Limeade) | D4: =IF(B4=1,"10 L jug",B4&" x 10 L jugs") | E4: =B4*Assumptions!$B$117 | F4: Sprite | G4: =E4*2.5 | H4: Cherry syrup | I4: =E4*1.5 | J4: Lime juice (bottled) | K4: =E4*1 | L4: Soda water | M4: =E4*1 | N4: Maraschino cherries (garnish) | O4: 0 | P4: Vodka | Q4: Blanco Tequila | R4: =E4*Assumptions!$B$39*Assumptions!$B$40 | S4: Sonic-style cherry limeade, opening night. Cherry syrup doubled to 1.5 oz/serving — at 0.75 against a full ounce of bottled lime it read sour and thin. Lime:syrup now 1:1.5. BUILD IT IN TWO HALVES: this pours in a 1-2 hour arrival window, so make ~17 servings, then build the second half when the first is a third down. The Sprite and soda water stay fizzy in the bottle until they are needed, which is the whole reason this one gets away with carbonation. ~0.75 tsp salt per half.
A5: Monday | B5: 1 | C5: Hard Reset (Watermelon-Mint Aqua Fresca) | D5: =IF(B5=1,"10 L jug",B5&" x 10 L jugs") | E5: =B5*Assumptions!$B$117 | F5: Watermelon (fresh, blended) | G5: =E5*Assumptions!$B$51 | H5: Agave syrup | I5: =E5*Assumptions!$B$54 | J5: Fresh mint (blended) | K5: 5 | L5: Fresh lime (squeeze) | M5: 0 | N5: Water (fill) | O5: 0 | P5: Blanco Tequila | Q5: Vodka | R5: =E5*Assumptions!$B$39*Assumptions!$B$40 | S5: Blend melon chunks with a handful of mint, strain rough, add agave + lime, top with STILL water to fill the jug (traditional fresca — skip tonic; optional soda-water splash per cup for fizz). ~1-2 melons per batch; melons travel fine unrefrigerated. Optional Blanco Tequila per cup makes it a watermelon margarita — melon, mint and lime are already the whole drink.
A6: Tuesday | B6: 1 | C6: Smoke Test (Lapsang Souchong Lemonade) | D6: =IF(B6=1,"10 L jug",B6&" x 10 L jugs") | E6: =B6*Assumptions!$B$117 | F6: Lapsang souchong | G6: =E6*Assumptions!$B$142 | H6: Lemonade | I6: =E6*3 | J6: Lime juice (bottled) | K6: =E6*0.5 | L6: Water/ice (fill) | M6: 0 | O6: 0 | P6: Whiskey | Q6: Spiced Rum | R6: =E6*Assumptions!$B$39*Assumptions!$B$40 | S6: Cold-steep ~2 oz of lapsang leaf overnight (or steep hot and chill) to make ~1.3 gal of STRONG smoky tea, then build the jug: 5 oz strong tea + 3 oz lemonade + 0.5 oz lime per serving, topped with water/ice. ~1.5 tsp salt per jug. Naturally still, so nothing to go flat. WARNING: lapsang runs from 'campfire' to 'ashtray' fast — brew it weaker than you think and taste before committing the jug. Optional Whiskey leans into the smoke.
A7: Wednesday | B7: 2 | C7: Red Flag (Agua de Jamaica) | D7: =IF(B7=1,"10 L jug",B7&" x 10 L jugs") | E7: =B7*Assumptions!$B$117 | F7: Dried hibiscus | G7: =E7*Assumptions!$B$124 | H7: Agave syrup | I7: =E7*0.5 | J7: Lime juice (bottled) | K7: =E7*0.5 | L7: Water (fill) | M7: 0 | O7: 0 | P7: Blanco Tequila | Q7: Spiced Rum | R7: =E7*Assumptions!$B$39*Assumptions!$B$40 | S7: Hibiscus agua fresca — steep the dried flowers, strain, cool, sweeten with agave, fill with cold water/ice. Cold-steeping overnight works too. TWO JUGS PREPPED (66 servings) — double a normal night, which is what the next-door party needs. A THIRD IS BACKUP ONLY and costs nothing to keep in reserve: one 1 lb bag of hibiscus is ~188 servings' worth, so the flowers for a third and fourth jug are already on the truck. If the party outruns two jugs, make the extra as concentrate — see 'Jug Build Steps'. Agave raised to 0.5 oz/serving; hibiscus is far tarter than the watermelon and was getting less sugar, which was backwards. Naturally still. ~1.5 tsp salt per jug. STAINS.
A8: Thursday | B8: 1 | C8: Gradient Descent (Malibu Sunrise) | D8: =IF(B8=1,"10 L jug",B8&" x 10 L jugs") | E8: =B8*Assumptions!$B$117 | F8: Orange juice | G8: =E8*3 | H8: Pineapple juice | I8: =E8*2.5 | J8: Fee Brothers Cherry Bitters (garnish, a few dashes per cup — not batched) | K8: 0 | L8: Lime juice (bottled) | M8: =E8*0.5 | N8: Passion fruit purée | O8: =E8*0.5 | P8: Coconut Rum | Q8: Spiced Rum | R8: =E8*Assumptions!$B$39*Assumptions!$B$40 | S8: Batch OJ + pineapple + passion fruit + lime in the jug, then top with water/ice. JUICE TRIMMED AGAIN — OJ 4 to 3 oz, pineapple 3 to 2.5 oz. At 8.5 oz of juice in a 10 oz cup this was essentially undiluted juice, the sugariest thing on the board and the most likely to make someone feel worse in the heat. Add 2-3 dashes of Fee Brothers Cherry Bitters to each CUP, not the jug, for a cherry note and a light color vein — swapped off grenadine 18 Aug 2026. Dashes are a subtler effect than the old 0.5 oz syrup drizzle: expect a soft tint, not the heavy syrup-sink gradient grenadine gave. ~1.5 tsp salt per jug. Optional Malibu per cup.
A9: Friday | B9: 1 | C9: Whore-chata | D9: =IF(B9=1,"10 L jug",B9&" x 10 L jugs") | E9: =B9*Assumptions!$B$117 | F9: Rice Dream Horchata (ready-to-drink) | G9: =E9*5 | H9: Coconut cream | I9: =E9*0.5 | J9: Vanilla syrup | K9: =E9*0.25 | L9: Water/ice (fill) | M9: 0 | P9: Spiced Rum | Q9: Bourbon | R9: =E9*Assumptions!$B$39*Assumptions!$B$40 | S9: Rice-milk base + cinnamon/vanilla syrup, batched cold; optional Spiced Rum float. SWITCHED TO READY-TO-DRINK 18 Aug 2026 — Rice Dream Horchata, 32 oz bottles, poured straight in rather than mixed from concentrate. Same 5 oz/serving pour as before (RAISED from 3 oz to 5 oz on the original concentrate build, so it stays generous here too); at 3 oz in a 10 oz cup it read as cinnamon water. Horchata should be opaque and rich. See Purchase List row 46 and Assumptions B16-18 (retired) for the sourcing history.
A10: Saturday | B10: 1 | C10: Sleep Mode (Peach Green Iced Tea) | D10: =IF(B10=1,"10 L jug",B10&" x 10 L jugs") | E10: =B10*Assumptions!$B$117 | F10: Green tea (cold-steeped) | G10: =E10*8 | H10: Peach syrup | I10: =E10*1 | J10: Lemon juice (bottled) | K10: =E10*0.5 | L10: Agave syrup | M10: =E10*0.25 | N10: Water/ice (fill) | O10: 0 | P10: Whiskey | Q10: Vodka | R10: =E10*Assumptions!$B$39*Assumptions!$B$40 | S10: THE SAME DRINK AS THE CLOSING SUNDAY’S GRACEFUL SHUTDOWN, ON PURPOSE. Saturday is the Catboy Café night — Sakura Kisses, Catboy Snot and Catboy Piss all land built-to-order on top of the full standing board — so the jug has to be the one thing nobody has to think about. Cold-steeped green tea, peach syrup, fresh lemon, a little agave. STEEP IT FRIDAY NIGHT with the rest of the Saturday prep, in its own sealed, labelled container; Sunday’s jug gets a SECOND steep on Saturday night. Naturally still, so nothing goes flat across a long night, and nothing needs stirring mid-service. ~1.5 tsp salt per jug. Taste BEFORE the ice — peach syrup varies, and this should read as tea with peach behind it, not peach squash. REPLACED BLUE SCREEN OF DEATH: the DIY Baja Blast wanted a per-cup Mountain Dew top-up from a recapped 2 L and a spirulina jug stirred every 20 minutes, which is the last thing the busiest night of the week needs. LEMON IS BOTTLED FOR THIS JUG (Purchase List row 44). 16.5 oz into a 10 L batch is about a dozen hand-squeezed lemons for something nobody can taste against the peach syrup and the tea. The fresh lemons are reserved for the per-drink squeezes on SCOBY Mule and Clear Cache.
A11: Sunday (closing) | B11: 1 | C11: Graceful Shutdown (Peach Green Iced Tea) | D11: =IF(B11=1,"10 L jug",B11&" x 10 L jugs") | E11: =B11*Assumptions!$B$117 | F11: Green tea (cold-steeped) | G11: =E11*8 | H11: Peach syrup | I11: =E11*1 | J11: Lemon juice (bottled) | K11: =E11*0.5 | L11: Agave syrup | M11: =E11*0.25 | N11: Water/ice (fill) | O11: 0 | P11: Whiskey | Q11: Vodka | R11: =E11*Assumptions!$B$39*Assumptions!$B$40 | S11: CLOSING SUNDAY, DAYTIME — the extra service day, not a night jug. Cold-steeped green tea, peach syrup, fresh lemon and a little agave. Cheapest jug of the week by a distance: the green tea comes out of the 100-bag camp box that camp barely touches, and the agave and lemons are already on the list. Serve it long over ice; cut it with soda water for anyone who wants it unsweetened. Steep the tea SATURDAY NIGHT — it is the one prep job that survives the busiest day of the week. LEMON IS BOTTLED FOR THIS JUG (Purchase List row 44). 16.5 oz into a 10 L batch is about a dozen hand-squeezed lemons for something nobody can taste against the peach syrup and the tea. The fresh lemons are reserved for the per-drink squeezes on SCOBY Mule and Clear Cache.
A12: ANY NIGHT | B12: — | C12: Turtle Soup (Mix of leftover alcohol) | S12: This is JUST for signage purposes, it will be made from whatever is left over.
A13: BACKUP | B13: — | C13: Salted Limeade (spare jug — no extra shopping) | D13: 10 L jug | S13: Fallback if a night runs dry or we want a 7th jug: lime juice 1oz + agave 0.5oz + water/ice to fill + ~1.5 tsp salt per jug. Deliberately left at 0 servings so it buys nothing — by the back half of the week we will already have the lime, syrup and salt on hand. Give it a serving count only if we decide to actually run it.
C14: Sakura Kisses (Described in Built Drinks)
A17: INGREDIENT TOTALS (jug-batch buys) | B17: Total oz | C17: +buffer | D17: Units to buy | E17: $/unit | F17: Subtotal | G17: Note
A18: Watermelon (whole melons) | B18: =SUMPRODUCT(('Jug Recipes'!$F$4:$F$15="Watermelon (fresh, blended)")*'Jug Recipes'!$G$4:$G$15)+SUMPRODUCT(('Jug Recipes'!$H$4:$H$15="Watermelon (fresh, blended)")*'Jug Recipes'!$I$4:$I$15)+SUMPRODUCT(('Jug Recipes'!$J$4:$J$15="Watermelon (fresh, blended)")*'Jug Recipes'!$K$4:$K$15)+SUMPRODUCT(('Jug Recipes'!$L$4:$L$15="Watermelon (fresh, blended)")*'Jug Recipes'!$M$4:$M$15)+SUMPRODUCT(('Jug Recipes'!$N$4:$N$15="Watermelon (fresh, blended)")*'Jug Recipes'!$O$4:$O$15) | C18: =B18*(1+Assumptions!$B$5) | D18: =CEILING(C18/Assumptions!$B$76,1) | E18: =Assumptions!$B$77 | F18: =D18*E18 | G18: Mon fresca — blend & strain
A19: Agave syrup (bottles) | B19: =SUMPRODUCT(('Jug Recipes'!$F$4:$F$15="Agave syrup")*'Jug Recipes'!$G$4:$G$15)+SUMPRODUCT(('Jug Recipes'!$H$4:$H$15="Agave syrup")*'Jug Recipes'!$I$4:$I$15)+SUMPRODUCT(('Jug Recipes'!$J$4:$J$15="Agave syrup")*'Jug Recipes'!$K$4:$K$15)+SUMPRODUCT(('Jug Recipes'!$L$4:$L$15="Agave syrup")*'Jug Recipes'!$M$4:$M$15)+SUMPRODUCT(('Jug Recipes'!$N$4:$N$15="Agave syrup")*'Jug Recipes'!$O$4:$O$15) | C19: =B19*(1+Assumptions!$B$5) | D19: =CEILING(C19/Assumptions!$B$132,1) | E19: =Assumptions!$B$133 | F19: =D19*E19 | G19: Mon fresca + Wed Red Flag
A20: TAB TOTAL (rows above + below) | F20: =F18+F19+SUM(F23:F32)
A21: Jug-format servings (for total-servings calc) | B21: =SUM(E4:E15)
A22: New special ingredients (Sun Cherry Bomb / Thu sunrise / Sat + Sun peach tea):
A23: Orange juice (64oz cartons) | B23: =SUMPRODUCT(('Jug Recipes'!$F$4:$F$15="Orange juice")*'Jug Recipes'!$G$4:$G$15)+SUMPRODUCT(('Jug Recipes'!$H$4:$H$15="Orange juice")*'Jug Recipes'!$I$4:$I$15)+SUMPRODUCT(('Jug Recipes'!$J$4:$J$15="Orange juice")*'Jug Recipes'!$K$4:$K$15)+SUMPRODUCT(('Jug Recipes'!$L$4:$L$15="Orange juice")*'Jug Recipes'!$M$4:$M$15)+SUMPRODUCT(('Jug Recipes'!$N$4:$N$15="Orange juice")*'Jug Recipes'!$O$4:$O$15) | C23: =B23*(1+Assumptions!$B$5) | D23: =CEILING(C23/Assumptions!$B$69,1) | E23: =Assumptions!$B$70 | F23: =D23*E23 | G23: Thu sunrise + Sat fresca
A24: Pineapple juice (24 x 8 oz cans) | B24: =SUMPRODUCT(('Jug Recipes'!$F$4:$F$15="Pineapple juice")*'Jug Recipes'!$G$4:$G$15)+SUMPRODUCT(('Jug Recipes'!$H$4:$H$15="Pineapple juice")*'Jug Recipes'!$I$4:$I$15)+SUMPRODUCT(('Jug Recipes'!$J$4:$J$15="Pineapple juice")*'Jug Recipes'!$K$4:$K$15)+SUMPRODUCT(('Jug Recipes'!$L$4:$L$15="Pineapple juice")*'Jug Recipes'!$M$4:$M$15)+SUMPRODUCT(('Jug Recipes'!$N$4:$N$15="Pineapple juice")*'Jug Recipes'!$O$4:$O$15) | C24: =B24*(1+Assumptions!$B$5) | D24: =CEILING(C24/Assumptions!$B$71,1) | E24: =Assumptions!$B$72 | F24: =D24*E24 | G24: Thu sunrise
A25: Grenadine (bottles) — RETIRED 18 Aug 2026, replaced by Fee Brothers Cherry Bitters (Purchase List) | B25: =SUMPRODUCT(('Jug Recipes'!$F$4:$F$15="Grenadine")*'Jug Recipes'!$G$4:$G$15)+SUMPRODUCT(('Jug Recipes'!$H$4:$H$15="Grenadine")*'Jug Recipes'!$I$4:$I$15)+SUMPRODUCT(('Jug Recipes'!$J$4:$J$15="Grenadine")*'Jug Recipes'!$K$4:$K$15)+SUMPRODUCT(('Jug Recipes'!$L$4:$L$15="Grenadine")*'Jug Recipes'!$M$4:$M$15)+SUMPRODUCT(('Jug Recipes'!$N$4:$N$15="Grenadine")*'Jug Recipes'!$O$4:$O$15) | C25: =B25*(1+Assumptions!$B$5) | D25: =CEILING(C25/Assumptions!$B$73,1) | E25: =Assumptions!$B$74 | F25: =D25*E25 | G25: RETIRED. Reads $0 on purpose — no ingredient is named "Grenadine" in the recipe grid any more, so the SUMPRODUCT above naturally zeroes. The Thursday jug's garnish is now Fee Brothers Cherry Bitters, bought as a flat bottle on Purchase List (was row 51, the old Grenadine line).
A26: Blue spirulina (jar) | D26: 1 | E26: =Assumptions!$B$75 | F26: =D26*E26 | G26: Grams not oz. NO LONGER A JUG INGREDIENT — Blue Screen of Death is retired and nothing in the jug block uses it. The jar is kept for exactly one job: tinting the Catboy Snot aloe bottle on Saturday (‘Dirty Soda - Built Drinks’ row 15). A pinch does it, so one 30 g jar is far more than enough, and there is no smaller sensible buy. Set the qty in column D to 0 if you drop the green tint as well.
A27: Lime juice (48oz bottles) | B27: =SUMPRODUCT(('Jug Recipes'!$F$4:$F$15="Lime juice (bottled)")*'Jug Recipes'!$G$4:$G$15)+SUMPRODUCT(('Jug Recipes'!$H$4:$H$15="Lime juice (bottled)")*'Jug Recipes'!$I$4:$I$15)+SUMPRODUCT(('Jug Recipes'!$J$4:$J$15="Lime juice (bottled)")*'Jug Recipes'!$K$4:$K$15)+SUMPRODUCT(('Jug Recipes'!$L$4:$L$15="Lime juice (bottled)")*'Jug Recipes'!$M$4:$M$15)+SUMPRODUCT(('Jug Recipes'!$N$4:$N$15="Lime juice (bottled)")*'Jug Recipes'!$O$4:$O$15)+SUMPRODUCT(('Dirty Soda - Built Drinks'!$H$3:$H$23="Lime juice (bottled)")*'Dirty Soda - Built Drinks'!$I$3:$I$23*'Dirty Soda - Built Drinks'!$B$3:$B$23) | C27: =B27*(1+Assumptions!$B$5) | D27: =CEILING(C27/Assumptions!$B$78,1) | E27: =Assumptions!$B$79 | F27: =D27*E27 | G27: Wed Cherry Limeade
A28: Maraschino cherries (jars) | D28: 2 | E28: =Assumptions!$B$80 | F28: =D28*E28 | G28: One cherry + juice splash per Wed cup (~35-40 cherries)
A29: Dried hibiscus (lb bags) | B29: =SUMPRODUCT(('Jug Recipes'!$F$4:$F$15="Dried hibiscus")*'Jug Recipes'!$G$4:$G$15)+SUMPRODUCT(('Jug Recipes'!$H$4:$H$15="Dried hibiscus")*'Jug Recipes'!$I$4:$I$15)+SUMPRODUCT(('Jug Recipes'!$J$4:$J$15="Dried hibiscus")*'Jug Recipes'!$K$4:$K$15)+SUMPRODUCT(('Jug Recipes'!$L$4:$L$15="Dried hibiscus")*'Jug Recipes'!$M$4:$M$15)+SUMPRODUCT(('Jug Recipes'!$N$4:$N$15="Dried hibiscus")*'Jug Recipes'!$O$4:$O$15)+'Dirty Soda - Built Drinks'!$B$22*Assumptions!$B$223 | C29: =B29*(1+Assumptions!$B$5) | D29: =CEILING(C29/Assumptions!$B$125,1) | E29: =Assumptions!$B$126 | F29: =D29*E29 | G29: Wed Red Flag — packs tiny and shelf-stable. LOCALHOST DROPPED HIBISCUS 11 Aug 2026 and became a standard margarita, so the Red Flag jug is the only committed draw again (~5.6 oz of the 16 oz bag). *** THE ~10.4 oz OF SPARE FLOWER IS SPOKEN FOR BY THE DAILY TEA STANDING TEA (Assumptions B252-B255) — do not reallocate it without checking there. ***
A30: Lapsang souchong (loose leaf) | B30: =SUMPRODUCT(('Jug Recipes'!$F$4:$F$15="Lapsang souchong")*'Jug Recipes'!$G$4:$G$15)+SUMPRODUCT(('Jug Recipes'!$H$4:$H$15="Lapsang souchong")*'Jug Recipes'!$I$4:$I$15)+SUMPRODUCT(('Jug Recipes'!$J$4:$J$15="Lapsang souchong")*'Jug Recipes'!$K$4:$K$15)+SUMPRODUCT(('Jug Recipes'!$L$4:$L$15="Lapsang souchong")*'Jug Recipes'!$M$4:$M$15)+SUMPRODUCT(('Jug Recipes'!$N$4:$N$15="Lapsang souchong")*'Jug Recipes'!$O$4:$O$15) | C30: =B30*(1+Assumptions!$B$5) | D30: =CEILING(C30/Assumptions!$B$143,1) | E30: =Assumptions!$B$144 | F30: =D30*E30 | G30: Tue Smoke Test — packs to nothing *** PART OF THIS IS SPOKEN FOR BY THE DAILY TEA STANDING TEA (Assumptions B252-B255) — do not reallocate the spare without checking there. ***
A31: Green tea teabags (Sun closing jug) | B31: =SUMPRODUCT(('Jug Recipes'!$F$4:$F$15="Green tea (cold-steeped)")*'Jug Recipes'!$G$4:$G$15)+SUMPRODUCT(('Jug Recipes'!$H$4:$H$15="Green tea (cold-steeped)")*'Jug Recipes'!$I$4:$I$15)+SUMPRODUCT(('Jug Recipes'!$J$4:$J$15="Green tea (cold-steeped)")*'Jug Recipes'!$K$4:$K$15)+SUMPRODUCT(('Jug Recipes'!$L$4:$L$15="Green tea (cold-steeped)")*'Jug Recipes'!$M$4:$M$15)+SUMPRODUCT(('Jug Recipes'!$N$4:$N$15="Green tea (cold-steeped)")*'Jug Recipes'!$O$4:$O$15) | C31: =B31*(1+Assumptions!$B$5) | D31: =CEILING(C31/128*Assumptions!$B$178,1) | E31: 0 | F31: 0 | G31: teabags — DRAWN FROM THE CAMP BOX, not a separate buy. TWO jugs now steep green tea, Saturday and the closing Sunday, so this roughly doubled — and it still barely dents the box. The green tea box on Purchase List row 62 holds Assumptions B179 bags; the camp iced tea and both jugs together use about a quarter of them. $0 here ON PURPOSE: costing it again would double-buy a box that goes home mostly full either way. *** PART OF THIS IS SPOKEN FOR BY THE DAILY TEA STANDING TEA (Assumptions B252-B255) — do not reallocate the spare without checking there. ***
A32: Lemon juice (32oz bottles) | B32: =SUMPRODUCT(('Jug Recipes'!$F$4:$F$15="Lemon juice (bottled)")*'Jug Recipes'!$G$4:$G$15)+SUMPRODUCT(('Jug Recipes'!$H$4:$H$15="Lemon juice (bottled)")*'Jug Recipes'!$I$4:$I$15)+SUMPRODUCT(('Jug Recipes'!$J$4:$J$15="Lemon juice (bottled)")*'Jug Recipes'!$K$4:$K$15)+SUMPRODUCT(('Jug Recipes'!$L$4:$L$15="Lemon juice (bottled)")*'Jug Recipes'!$M$4:$M$15)+SUMPRODUCT(('Jug Recipes'!$N$4:$N$15="Lemon juice (bottled)")*'Jug Recipes'!$O$4:$O$15) | C32: =B32*(1+Assumptions!$B$5) | D32: =CEILING(C32/Assumptions!$B$227,1) | E32: =Assumptions!$B$228 | F32: =D32*E32 | G32: Sat Sleep Mode + Sun Graceful Shutdown — 16.5 oz each. Mirrors the bottled lime on row 27: batch jugs take bottled, per-drink squeezes take fresh.

Sheet Jug Build Steps
A1: Jug Build Steps — how to actually make each night
A3: The procedure card. 'Jug Recipes' says WHAT goes in; this says HOW and IN WHAT ORDER. Quantities in column F are live — they follow the # jugs on Jug Recipes, so they stay right if a night gets scaled up. Written for someone who has never made these, reading in the dark. FOR THE DESIGNER: this is one card per night, plus the standing block at the bottom which goes on the permanent card alongside the Main Instructions from 'Daily Schedule'.
A5: Day | B5: Drink | C5: Start by / time needed | D5: NIGHT BEFORE | E5: BUILD — in this order | F5: Batch quantities (live) | G5: AT SERVICE
A6: ='Jug Recipes'!A4 | B6: ='Jug Recipes'!C4 | C6: 45 min before the party. Shortest build of the week. | D6: Nothing. | E6: BUILD IN HALVES — this pours in a 1-2 hour window. 1. Half the cherry syrup + half the lime into the dispenser. 2. Cold water to about half full. 3. Half the Sprite and soda water, poured DOWN THE INSIDE WALL. One gentle stir — do not whisk, you will kill the fizz. 4. Ice to fill. ~0.75 tsp salt. 5. Taste. 6. Build the second half the same way when the first is a third down. Do NOT pre-mix both. | F6: =IF('Jug Recipes'!G4>0,'Jug Recipes'!F4&" "&TEXT('Jug Recipes'!G4,"0.#")&" oz"&CHAR(10),"")&IF('Jug Recipes'!I4>0,'Jug Recipes'!H4&" "&TEXT('Jug Recipes'!I4,"0.#")&" oz"&CHAR(10),"")&IF('Jug Recipes'!K4>0,'Jug Recipes'!J4&" "&TEXT('Jug Recipes'!K4,"0.#")&" oz"&CHAR(10),"")&IF('Jug Recipes'!M4>0,'Jug Recipes'!L4&" "&TEXT('Jug Recipes'!M4,"0.#")&" oz"&CHAR(10),"")&IF('Jug Recipes'!O4>0,'Jug Recipes'!N4&" "&TEXT('Jug Recipes'!O4,"0.#")&" oz"&CHAR(10),"") | G6: Pour and go. Maraschino cherry on top if supplies allow. Flatness is not a problem here — it is gone inside two hours.
A7: ='Jug Recipes'!A5 | B7: ='Jug Recipes'!C5 | C7: 90 minutes. THE LONGEST BUILD OF THE WEEK — start early. | D7: Nothing. Melons travel fine unrefrigerated. | E7: 1. Cut 2 melons into chunks. Reckon ~90 oz of juice per melon. 2. Blend in batches with a handful of mint. The 12 V blender is small — plan on 4-6 rounds. 3. Strain rough through the fine mesh into a gallon container. Some pulp is good; you are not making juice. 4. Strained juice + agave + lime into the dispenser. 5. STILL water to fill. No tonic, no soda. 6. 1.5 tsp salt. Stir. | F7: =IF('Jug Recipes'!G5>0,'Jug Recipes'!F5&" "&TEXT('Jug Recipes'!G5,"0.#")&" oz"&CHAR(10),"")&IF('Jug Recipes'!I5>0,'Jug Recipes'!H5&" "&TEXT('Jug Recipes'!I5,"0.#")&" oz"&CHAR(10),"")&IF('Jug Recipes'!K5>0,'Jug Recipes'!J5&" "&TEXT('Jug Recipes'!K5,"0.#")&" oz"&CHAR(10),"")&IF('Jug Recipes'!M5>0,'Jug Recipes'!L5&" "&TEXT('Jug Recipes'!M5,"0.#")&" oz"&CHAR(10),"")&IF('Jug Recipes'!O5>0,'Jug Recipes'!N5&" "&TEXT('Jug Recipes'!O5,"0.#")&" oz"&CHAR(10),"") | G7: Stir before each pour — pulp settles. Soda-water splash per cup if someone wants fizz. Blanco Tequila makes it a watermelon margarita.
A8: ='Jug Recipes'!A6 | B8: ='Jug Recipes'!C6 | C8: 30 min, plus an overnight steep started Monday. | D8: MONDAY NIGHT: cold-steep ~2 oz of lapsang leaf in ~1.3 gal of cold water. Seal it. | E8: 1. STRAIN THE LEAVES OUT FIRST. Left in, it keeps extracting and goes from campfire to ashtray. 2. TASTE THE TEA ON ITS OWN. This is the decision point — if it is acrid, cut it with water BEFORE it meets anything else. 3. Strong tea + lemonade + lime into the dispenser. 4. Water/ice to fill. 1.5 tsp salt. 5. Taste again. | F8: =IF('Jug Recipes'!G6>0,'Jug Recipes'!F6&" "&TEXT('Jug Recipes'!G6,"0.#")&" oz"&CHAR(10),"")&IF('Jug Recipes'!I6>0,'Jug Recipes'!H6&" "&TEXT('Jug Recipes'!I6,"0.#")&" oz"&CHAR(10),"")&IF('Jug Recipes'!K6>0,'Jug Recipes'!J6&" "&TEXT('Jug Recipes'!K6,"0.#")&" oz"&CHAR(10),"")&IF('Jug Recipes'!M6>0,'Jug Recipes'!L6&" "&TEXT('Jug Recipes'!M6,"0.#")&" oz"&CHAR(10),"")&IF('Jug Recipes'!O6>0,'Jug Recipes'!N6&" "&TEXT('Jug Recipes'!O6,"0.#")&" oz"&CHAR(10),"") | G8: Naturally still, so nothing is going flat. No rush on this one.
A9: ='Jug Recipes'!A7 | B9: ='Jug Recipes'!C7 | C9: 2 hours. Still the biggest build of the week. | D9: TUESDAY NIGHT: cold-steep the dried hibiscus for TWO jugs. Steeping hot on the day works too, but it then has to cool. | E9: 1. Steep, then STRAIN THOROUGHLY. Flowers left in turn it bitter and astringent. 2. Two jugs, two dispensers — it fits, no juggling. 3. Per dispenser: hibiscus tea + agave + lime + cold water to fill. 4. 1.5 tsp salt per jug. Taste — it should read properly sweet, not just tart. 5. IF THE PARTY OUTRUNS TWO JUGS: you have flowers for plenty more. Steep a third batch as CONCENTRATE and hold it in a 1-gallon container — concentrate takes about a third the space of finished drink — then cut it into a dispenser as one empties. | F9: =IF('Jug Recipes'!G7>0,'Jug Recipes'!F7&" "&TEXT('Jug Recipes'!G7,"0.#")&" oz"&CHAR(10),"")&IF('Jug Recipes'!I7>0,'Jug Recipes'!H7&" "&TEXT('Jug Recipes'!I7,"0.#")&" oz"&CHAR(10),"")&IF('Jug Recipes'!K7>0,'Jug Recipes'!J7&" "&TEXT('Jug Recipes'!K7,"0.#")&" oz"&CHAR(10),"")&IF('Jug Recipes'!M7>0,'Jug Recipes'!L7&" "&TEXT('Jug Recipes'!M7,"0.#")&" oz"&CHAR(10),"")&IF('Jug Recipes'!O7>0,'Jug Recipes'!N7&" "&TEXT('Jug Recipes'!O7,"0.#")&" oz"&CHAR(10),"") | G9: WARN PEOPLE IT STAINS — cups, hands, clothing, especially anything white. Naturally still, so there is no hurry once it is built.
A10: ='Jug Recipes'!A8 | B10: ='Jug Recipes'!C8 | C10: 30 min. | D10: Nothing. | E10: 1. OJ + pineapple + passion fruit purée + lime into the dispenser. 2. Water/ice to fill. 1.5 tsp salt. 3. Stir well — the purée sinks. 4. THE BITTERS DO NOT GO IN THE JUG. Keep the Fee Brothers Cherry Bitters bottle at the bar. | F10: =IF('Jug Recipes'!G8>0,'Jug Recipes'!F8&" "&TEXT('Jug Recipes'!G8,"0.#")&" oz"&CHAR(10),"")&IF('Jug Recipes'!I8>0,'Jug Recipes'!H8&" "&TEXT('Jug Recipes'!I8,"0.#")&" oz"&CHAR(10),"")&IF('Jug Recipes'!K8>0,'Jug Recipes'!J8&" "&TEXT('Jug Recipes'!K8,"0.#")&" oz"&CHAR(10),"")&IF('Jug Recipes'!M8>0,'Jug Recipes'!L8&" "&TEXT('Jug Recipes'!M8,"0.#")&" oz"&CHAR(10),"")&IF('Jug Recipes'!O8>0,'Jug Recipes'!N8&" "&TEXT('Jug Recipes'!O8,"0.#")&" oz"&CHAR(10),"") | G10: Pour the cup, THEN add 2-3 dashes of Fee Brothers Cherry Bitters on top. Swapped off grenadine 18 Aug 2026 — expect a cherry note and a light color tint, not the old heavy syrup-sink gradient. Orange slice or cherry if supplies allow.
A11: ='Jug Recipes'!A9 | B11: ='Jug Recipes'!C9 | C11: 30 min for the jug. The rest of tonight belongs to Saturday. | D11: Nothing for this drink — but TONIGHT IS THE BIG SATURDAY PREP. See the Daily Schedule. | E11: 1. Whisk the coconut cream smooth in a little warm water FIRST. Straight from the bottle it clumps and you will never get it out. 2. Rice Dream Horchata (shake well, it settles) + whisked coconut cream + vanilla syrup — no dilution needed, it's ready-to-drink. 3. Water/ice to fill. 1.5 tsp salt. 4. WHISK, do not just stir. | F11: =IF('Jug Recipes'!G9>0,'Jug Recipes'!F9&" "&TEXT('Jug Recipes'!G9,"0.#")&" oz"&CHAR(10),"")&IF('Jug Recipes'!I9>0,'Jug Recipes'!H9&" "&TEXT('Jug Recipes'!I9,"0.#")&" oz"&CHAR(10),"")&IF('Jug Recipes'!K9>0,'Jug Recipes'!J9&" "&TEXT('Jug Recipes'!K9,"0.#")&" oz"&CHAR(10),"")&IF('Jug Recipes'!M9>0,'Jug Recipes'!L9&" "&TEXT('Jug Recipes'!M9,"0.#")&" oz"&CHAR(10),"")&IF('Jug Recipes'!O9>0,'Jug Recipes'!N9&" "&TEXT('Jug Recipes'!O9,"0.#")&" oz"&CHAR(10),"") | G11: STIR BEFORE EVERY POUR — rice milk settles hard and fast. Cinnamon dust on top. Spiced Rum float on request.
A12: ='Jug Recipes'!A10 | B12: ='Jug Recipes'!C10 | C12: 20 min on the day, plus an overnight cold steep started Friday. Deliberately the easiest build of the week — Saturday needs a jug that looks after itself. | D12: FRIDAY NIGHT: cold-steep ~10 green teabags in ~2 gal of cold water and seal it. This is a SECOND, SEPARATE steep from Sunday’s — same recipe, its own container, its own label, or you will pour tomorrow’s jug into today’s. Cold-steeping cannot go bitter the way a hot steep can, so it survives being forgotten in the middle of the Saturday prep. | E12: 1. Pull the teabags. Do not squeeze them. 2. Tea into the dispenser, then peach syrup, then lemon, then agave. 3. Taste BEFORE the ice. Peach syrup varies; this should read as tea with peach behind it, not peach squash. 4. Water/ice to fill. 1.5 tsp salt. 5. *** NO MOUNTAIN DEW AND NO SPIRULINA. *** That was Blue Screen of Death and it is gone. Nothing on this jug gets topped up per cup and nothing needs stirring. | F12: =IF('Jug Recipes'!G10>0,'Jug Recipes'!F10&" "&TEXT('Jug Recipes'!G10,"0.#")&" oz"&CHAR(10),"")&IF('Jug Recipes'!I10>0,'Jug Recipes'!H10&" "&TEXT('Jug Recipes'!I10,"0.#")&" oz"&CHAR(10),"")&IF('Jug Recipes'!K10>0,'Jug Recipes'!J10&" "&TEXT('Jug Recipes'!K10,"0.#")&" oz"&CHAR(10),"")&IF('Jug Recipes'!M10>0,'Jug Recipes'!L10&" "&TEXT('Jug Recipes'!M10,"0.#")&" oz"&CHAR(10),"")&IF('Jug Recipes'!O10>0,'Jug Recipes'!N10&" "&TEXT('Jug Recipes'!O10,"0.#")&" oz"&CHAR(10),"") | G12: Pour and go. Naturally still, so there is nothing to keep fizzy and nothing to stir — which is the entire point on the night the three reveals land. Soda-water splash for anyone who wants it longer or less sweet. Same drink as tomorrow, so anyone who liked it can have it again.
A13: ='Jug Recipes'!A11 | B13: ='Jug Recipes'!C11 | C13: 20 min on the day, plus an overnight cold steep started Saturday. Easiest build of the week — which is the point, on the day everyone is packing. | D13: SATURDAY NIGHT: cold-steep ~10 green teabags in ~2 gal of cold water and seal it. Cold-steeping cannot go bitter the way a hot steep can, so this one survives being forgotten until morning. | E13: 1. Pull the teabags. Do not squeeze them. 2. Tea into the dispenser, then peach syrup, then lemon, then agave. 3. Taste BEFORE the ice. Peach syrup varies; this should read as tea with peach behind it, not peach squash. 4. Water/ice to fill. 1.5 tsp salt. | F13: =IF('Jug Recipes'!G11>0,'Jug Recipes'!F11&" "&TEXT('Jug Recipes'!G11,"0.#")&" oz"&CHAR(10),"")&IF('Jug Recipes'!I11>0,'Jug Recipes'!H11&" "&TEXT('Jug Recipes'!I11,"0.#")&" oz"&CHAR(10),"")&IF('Jug Recipes'!K11>0,'Jug Recipes'!J11&" "&TEXT('Jug Recipes'!K11,"0.#")&" oz"&CHAR(10),"")&IF('Jug Recipes'!M11>0,'Jug Recipes'!L11&" "&TEXT('Jug Recipes'!M11,"0.#")&" oz"&CHAR(10),"")&IF('Jug Recipes'!O11>0,'Jug Recipes'!N11&" "&TEXT('Jug Recipes'!O11,"0.#")&" oz"&CHAR(10),"") | G13: Daytime service, so it goes out warm-adjacent fast — keep the dispenser out of the sun and the ice topped up. Soda-water splash for anyone who wants it unsweetened.
A15: EVERY JUG, EVERY TIME — the standing rules
A16: Wipe the dispenser and the spigot before you start. Dust gets into everything, and the spigot is the bit everyone touches.
A17: ORDER MATTERS: syrups and juices first, then water, then ICE LAST. Ice first means it melts while you are still stirring and you end up with a weak jug.
A18: SALT EVERY JUG — about 1.5 tsp per 10 L. It is not optional and it is not for flavour exactly; it is what makes a batch taste finished instead of watery in the heat.
A19: TASTE IT BEFORE IT GOES OUT. Every recipe here is a starting point, not a law. Fruit varies, steeps vary, and nobody will know it was wrong except the 33 people who drink it.
A20: BATCH BEFORE SERVICE OPENS, never during. A jug built in a rush is a jug built wrong.
A21: Label the dispenser. The special changes every night and the sign from yesterday is a lie.
A22: If a jug runs dry early there is a Salted Limeade fallback on 'Jug Recipes' row 13 that needs no extra shopping.

Sheet Camp Drinks
A1: Camp Drinks — bulk, self-serve, not bar service
A3: Big-batch drinks that live on the camp table, not the bar: caffeine in the morning, electrolytes all day, two unsweetened iced teas plus one sweetened winter melon tea, and a canned block (Celsius, hard seltzer, Spindrift, ginger beer) counted by the can rather than by the gallon, plus the coffee creamer. Everything here runs EIGHT days (Assumptions B81) — Sunday through the closing Sunday. Quantities are live from the Assumptions tab — yellow cells there drive gallons. These feed the Purchase List rows tagged 'Camp bulk'.
A5: Drink | B5: Gallons | C5: Servings (10oz) | D5: What to buy | E5: Qty | F5: Unit | G5: $/unit | H5: Subtotal | I5: Note
A6: Cold brew coffee | B6: =Assumptions!$B$81*Assumptions!$B$82 | C6: =B6*128/10 | D6: Stone Street COARSE cold brew coffee (5 lb bags) | E6: =CEILING(B6*Assumptions!$B$83/Assumptions!$B$84,1) | F6: lbs | G6: =Assumptions!$B$85 | H6: =E6*G6 | I6: Brewed as concentrate then cut ~1:1. Assumptions B82 sets gallons/day. SWITCHED TO GROUND 18 Aug 2026 (was whole bean, which needed a grinder nobody has) — 14 lb ordered, mixed bag sizes since 5 lb ground wasn't available in enough quantity. RATIO CORRECTED same day: 0.5 lb/gal (Assumptions B83), not the original 1 — 24 finished gal x 0.5 = 12 lb needed, so 14 lb carries a ~2 lb buffer, a bit more generous than the original plan's 1 lb spare. Steep it in the strainer bags on Supplies row 28: grounds go IN the bag, bag comes out, no second filtration pass.
A7: Electrolyte mix | B7: =Assumptions!$B$81*Assumptions!$B$86 | C7: =B7*128/10 | D7: Powder canisters | E7: =CEILING(B7/Assumptions!$B$87,1) | F7: canisters | G7: =Assumptions!$B$88 | H7: =E7*G7 | I7: Gatorade-style 51oz canister, ~6 gal each. Assumptions B86 sets gallons/day.
A8: Winter melon tea (dong gua cha) | B8: =Assumptions!$B$135 | C8: =B8*128/10 | D8: Tea/sugar blocks | E8: =CEILING(B8/Assumptions!$B$136,1) | F8: blocks | G8: =Assumptions!$B$137 | H8: =E8*G8 | I8: Winter melon (white gourd) sugar block, dissolved in hot water then chilled — a classic Chinese/Taiwanese sweet iced tea, REPLACING SUAN MEI TANG 18 Aug 2026. Served cold and self-serve from the DEDICATED TEA DISPENSER (Supplies row 23, third unit) — brewed in two batches, Wednesday and Friday. NOTE: unlike the other two camp teas, this one is SWEET, not unsweetened — label it clearly so it doesn't get mistaken for the unsweetened pair. *** RESEARCHED 18 Aug 2026, NOT A CHECKED RECEIPT: *** yield and price are estimated from a handful of Asian-grocery listings (Weee!, Yami) rather than a single confirmed SKU — see Assumptions B136/B137 for the basis. Standard prep is to simmer the block in water until dissolved, then dilute with water/ice to taste; treat the block-per-gallon figure as a starting point and adjust to the real product's own instructions once it arrives.
A9: Mugicha (roasted barley tea) | B9: =Assumptions!$B$138 | C9: =B9*128/10 | D9: Teabags | E9: =CEILING(B9*Assumptions!$B$139/Assumptions!$B$140,1) | F9: boxes | G9: =Assumptions!$B$141 | H9: =E9*G9 | I9: Cold-steep overnight, serve iced and unsweetened. Shares the dedicated tea dispenser with the suan mei tang — brewed in two batches, Thursday and Saturday. Label it: unsweetened surprises people.
A10: Green tea (iced) | B10: =Assumptions!$B$177 | C10: =B10*128/10 | D10: Teabags | E10: =CEILING(B10*Assumptions!$B$178/Assumptions!$B$179,1) | F10: boxes | G10: =Assumptions!$B$180 | H10: =E10*G10 | I10: Cold-steep overnight, serve iced and unsweetened. THIRD tea on the dedicated dispenser (Supplies row 23) — suan mei tang and mugicha already share it, so either stagger a third brew slot or add a fourth dispenser. Label it unsweetened.
A11: Tangerine juice (RATIONED) | B11: =Assumptions!$B$194*Assumptions!$B$195/128 | C11: =B11*128/10 | D11: Quart cartons, chilled | E11: =Assumptions!$B$194 | F11: quarts | G11: =Assumptions!$B$196 | H11: =E11*G11 | I11: *** RATION IT. *** 4 quarts is ~13 servings against an eight-day burn — this is a treat, not a staple, and it will be gone by Monday lunchtime if it goes out with everything else. Put ONE quart out at a time, in the morning alongside the cold brew, and keep the rest out of the cooler people browse. It is the only thing on the camp block that tastes like it came from outside the desert, which is exactly why it disappears.
