Workbook

Sheet Assumptions
A1: Future Turtles Drinks — Supply Model (Burning Man 2026)
A3: KEY INPUTS — yellow cells are editable
A4: Input | B4: Value | C4: Note
A5: Buffer (waste/over-pour) | B5: 0.15 | C5: Applied to consumables.
A6: Cans per case (base soda) | B6: 24 | C6: 12 oz can case.
A7: Can size (oz) | B7: 12 | C7: Standard can.
A8: Syrup bottle size (oz) | B8: 25.4 | C8: Torani 750ml.
A9: Cream of coconut (oz/bottle) | B9: 22 | C9: 22oz squeeze bottle (Amazon).
A10: Half & half (oz/quart) — LEGACY | B10: 32 | C10: Dairy dropped — replaced by cream of coconut squeeze bottles.
A11: Keg size (gal) | B11: 5 | C11: All 5 kegs assumed 5 gal.
A12: Servings per 5gal keg | B12: =FLOOR((B11*128-B121)/B120,1) | C12: Derived: (keg gal x 128 - loss) / pour size. Change B120 to resize every keg count in the model.
A13: Squirt bottle size (oz) — LEGACY | B13: 67.6 | C13: Legacy 2L sizing — Squirt now bought in 12oz cans like the other sodas.
A15: UNIT PRICES
A16: Base soda — $/case (24) | B16: 25
A17: Lemonade — $/gallon | B17: 1.25 | C17: Cost per FINISHED gallon. Now priced as liquid concentrate: one ~$5 bottle makes ~8 gal, so the 4-gal requirement is a single bottle. Set this to 4-6 to switch back to ready-to-drink jugs — Purchase List row 6 re-prices itself either way.
A18: Horchata mix — $/case-equiv | B18: 12
A19: Syrup — $/bottle | B19: 9
A20: Cream of coconut — $/bottle | B20: 7
A21: Half & half — $/quart — LEGACY | B21: 3.5
A22: Soda water — $/case | B22: 18
A23: Squirt — (now in cans; see soda case price) | B23: 2.5
A24: Cider keg — $/keg | B24: 160
A25: Kombucha keg — $/keg | B25: 130
A26: Beer keg — $/keg | B26: 180
A27: Green tea keg — $/keg | B27: 130
A28: Keg add-ons/garnish — $/keg avg | B28: 25
A29: Kombucha | B29: 0.35 | C29: Kombucha Mule add-ins (lemon/sugar/ginger beer); Tang Dynasty extras are itemized separately.
A31: KEG EQUIPMENT — RENTED (Mike's Liquors)
A32: Keg deposit — each (REFUNDABLE) | B32: 50 | C32: Cash needed up front, returned with the empties — excluded from program cost.
A33: Double jockey box (2 taps) — $ per 4-day rental | B33: 150 | C33: Ice-cooled coil box; no kegerator needed.
A34: Rental periods (12 days = 3 x 4-day) | B34: 3
A35: CO2 refill — $ each | B35: 59
A36: CO2 refills — count | B36: 2 | C36: 10lb pushes ~5-7 kegs; 2nd fill covers heat/venting losses.
A38: LIQUOR (OPTIONAL ADD-ON)
A39: % of drinks made alcoholic | B39: 0.35 | C39: Applied to servings per recipe to size liquor needs.
A40: Liquor pour per alcoholic drink (oz) | B40: 1.5 | C40: Standard single shot.
A41: Liquor bottle size (oz) | B41: 25.4 | C41: 750ml standard.
A42: Vodka — $/bottle | B42: 24 | C42: Consider peach/vanilla flavored vodka for Peaches & Creamed / Orange Cream-sicle.
A43: Coconut Rum — $/bottle | B43: 24 | C43: e.g. Malibu.
A44: Bourbon — $/bottle | B44: 28
...

Sheet Totals by Type
A1: Drink Totals & Cost by Section
A3: Live-linked to every other tab. Drinks come from Kegs / Daily Schedule / Recipes; costs roll up from the Purchase List Category column, then Section C splits each shared pool across the four drink types by a stated basis, so no type is over- or under-charged.
A5: A. DRINKS BY TYPE
A6: Drink type | B6: Drinks | C6: Share | D6: Cost | E6: $ / drink
A7: Keg — poured straight from tap | B7: =Kegs!$C$13 | C7: =B7/$B$11 | D7: =D49 | E7: =D7/B7
A8: Jug — nightly 10 L daily special | B8: =SUM('Daily Schedule'!$E$4:$E$15) | C8: =B8/$B$11 | D8: =E49 | E8: =D8/B8
A9: Dirty soda — BUILT off a keg | B9: =(Recipes!$B$3+Recipes!$B$4+Recipes!$B$11+Recipes!$B$13+Recipes!$B$14) | C9: =B9/$B$11 | D9: =F49 | E9: =D9/B9
A10: Dirty soda — canned base | B10: =Recipes!$B$19-(Recipes!$B$3+Recipes!$B$4+Recipes!$B$11+Recipes!$B$13+Recipes!$B$14) | C10: =B10/$B$11 | D10: =G49 | E10: =D10/B10
A11: TOTAL DRINKS / DIRECTLY ATTRIBUTED COST | B11: =SUM(B7:B10) | C11: =SUM(C7:C10) | D11: =SUM(D7:D10) | E11: =D11/B11
A12: Shared cost — not tied to one drink type | D12: =D29+D30+D31+D32+D33
A13: TOTAL PROGRAM COST (excl. refundable deposits) | D13: =D11+D12 | E13: =D13/B11
A15: The four built drinks (Michelada, SCOBY-Dew, Tang Dynasty, Sakura Kisses, Clear Cache) pour off a keg but are counted here as dirty sodas, because that is where their build cost sits — so they get their own row. Kombucha kegs: 40 Tang + 40 SCOBY-Dew + the rest straight. Mexican Lager: 30 Michelada + rest straight. Green tea: 33 Sakura Kisses + rest straight. Every keg row subtracts its built drinks, so nothing is double-counted, and Section C charges built drinks the same per-serving keg cost as a straight pour.
A17: B. COST BY SECTION — straight from the Purchase List categories
A18: Section | B18: Purchase List category | C18: Share | D18: Cost | E18: $ / drink | F18: Rolls up to
A19: Base soda, lemonade, horchata & soda water | B19: Soda | C19: =D19/$D$34 | D19: =SUMIF('Purchase List'!$C$5:$C$73,"Soda",'Purchase List'!$F$5:$F$73) | E19: =D19/$B$11 | F19: Jug + canned dirty soda
A20: Syrups & fruit purees | B20: Syrup | C20: =D20/$D$34 | D20: =SUMIF('Purchase List'!$C$5:$C$73,"Syrup",'Purchase List'!$F$5:$F$73) | E20: =D20/$B$11 | F20: Jug + built + canned
A21: Cream of coconut | B21: Dairy/cream | C21: =D21/$D$34 | D21: =SUMIF('Purchase List'!$C$5:$C$73,"Dairy/cream",'Purchase List'!$F$5:$F$73) | E21: =D21/$B$11 | F21: Jug + canned dirty soda
A22: Built-drink extras + rim salt | B22: Built drink | C22: =D22/$D$34 | D22: =SUMIF('Purchase List'!$C$5:$C$73,"Built drink",'Purchase List'!$F$5:$F$73) | E22: =D22/$B$11 | F22: Built drinks
A23: Fresh produce (Thirst Trap cucumber + lime) | B23: Fresh produce | C23: =D23/$D$34 | D23: =SUMIF('Purchase List'!$C$5:$C$73,"Fresh produce",'Purchase List'!$F$5:$F$73) | E23: =D23/$B$11 | F23: Canned dirty soda
A24: Kegs (cider, kombucha x3, ales, lager, green tea) | B24: Keg | C24: =D24/$D$34 | D24: =SUMIF('Purchase List'!$C$5:$C$73,"Keg",'Purchase List'!$F$5:$F$73) | E24: =D24/$B$11 | F24: Keg + built drinks
A25: Keg add-ons (aloe, lychee) | B25: Keg add-on | C25: =D25/$D$34 | D25: =SUMIF('Purchase List'!$C$5:$C$73,"Keg add-on",'Purchase List'!$F$5:$F$73) | E25: =D25/$B$11 | F25: Keg
A26: Jockey box rental, CO2, lines | B26: Rental/gas | C26: =D26/$D$34 | D26: =SUMIF('Purchase List'!$C$5:$C$73,"Rental/gas",'Purchase List'!$F$5:$F$73) | E26: =D26/$B$11 | F26: Keg + built drinks
A27: Ice tubs for the live kegs | B27: Hardware | C27: =D27/$D$34 | D27: =SUMIF('Purchase List'!$C$5:$C$73,"Hardware",'Purchase List'!$F$5:$F$73) | E27: =D27/$B$11 | F27: Keg + built drinks
A28: Daily special (jug) ingredients | B28: Daily Special | C28: =D28/$D$34 | D28: =SUMIF('Purchase List'!$C$5:$C$73,"Daily Special",'Purchase List'!$F$5:$F$73) | E28: =D28/$B$11 | F28: Jug
A29: Liquor (optional add-on) | B29: Liquor | C29: =D29/$D$34 | D29: =SUMIF('Purchase List'!$C$5:$C$73,"Liquor",'Purchase List'!$F$5:$F$73) | E29: =D29/$B$11 | F29: Shared
A30: Fresh garnish & produce | B30: Garnish | C30: =D30/$D$34 | D30: =SUMIF('Purchase List'!$C$5:$C$73,"Garnish",'Purchase List'!$F$5:$F$73) | E30: =D30/$B$11 | F30: Shared
A31: Misc — catch-all (nothing tagged Misc right now) | B31: Misc | C31: =D31/$D$34 | D31: =SUMIF('Purchase List'!$C$5:$C$73,"Misc",'Purchase List'!$F$5:$F$73) | E31: =D31/$B$11 | F31: Shared
A32: Camp bulk (cold brew, electrolytes, suan mei tang, mugicha) | B32: Camp bulk | C32: =D32/$D$34 | D32: =SUMIF('Purchase List'!$C$5:$C$73,"Camp bulk",'Purchase List'!$F$5:$F$73) | E32: =D32/$B$11 | F32: Shared — see Camp Drinks tab
A33: Bar add-ons (tonic, soda water, Red Bull, bitters) | B33: Add-on | C33: =D33/$D$34 | D33: =SUMIF('Purchase List'!$C$5:$C$73,"Add-on",'Purchase List'!$F$5:$F$73) | E33: =D33/$B$11 | F33: Shared — see Bar Add-Ons tab
A34: PROGRAM TOTAL (excl. refundable deposits) | C34: =SUM(C19:C33) | D34: =SUM(D19:D33) | E34: =D34/$B$11
A36: Memo — keg deposits (REFUNDABLE, cash up front) | B36: Deposit | D36: =SUMIF('Purchase List'!$C$5:$C$73,"Deposit",'Purchase List'!$F$5:$F$73)
A37: Check: sections + deposits vs Purchase List total (should be $0) | D37: =D34+D36-'Purchase List'!$F$74
A39: C. SHARED-INPUT ALLOCATION — how each pool splits across the four types
A40: Shared input pool | B40: Allocation basis | C40: Pool $ | D40: → Keg straight | E40: → Jug | F40: → Built drinks | G40: → Canned dirty soda
A41: Keg liquid + tap infrastructure | B41: servings drawn off the kegs | C41: =D24+D26+D27 | D41: =C41*$B$59/($B$59+$B$60) | E41: 0 | F41: =C41*$B$60/($B$59+$B$60) | G41: =C41-D41-E41-F41
A42: Keg add-ons (aloe, lychee) | B42: 100% straight pours | C42: =D25 | D42: =C42 | E42: 0 | F42: 0 | G42: 0
A43: Base soda, lemonade, horchata & soda water | B43: oz consumed | C43: =D19 | D43: 0 | E43: =C43*$B$53/$B$52 | F43: 0 | G43: =C43-D43-E43-F43
A44: Syrups & fruit purees | B44: oz consumed | C44: =D20 | D44: 0 | E44: =C44*$B$55/$B$54 | F44: =C44*$B$56/$B$54 | G44: =C44-D44-E44-F44
A45: Cream of coconut | B45: oz consumed | C45: =D21 | D45: 0 | E45: =C45*$B$58/$B$57 | F45: 0 | G45: =C45-D45-E45-F45
A46: Built-drink extras + rim salt | B46: 100% built drinks | C46: =D22 | D46: 0 | E46: 0 | F46: =C46 | G46: 0
...

Sheet Recipes
A1: Dirty Soda Recipes — absolute drink counts (per-serving oz)
A2: Recipe | B2: Servings | C2: (share) | D2: Base soda | E2: Base oz | F2: Syrup A | G2: A oz | H2: Syrup B | I2: B oz | J2: Soda water oz | K2: Coconut cream oz | L2: Special / garnish | M2: Liquor (optional) | N2: Liquor oz needed
A3: Tang Dynasty (built) | B3: 40 | C3: =B3/$B$19 | D3: Kombucha keg | E3: 4 | F3: Tangerine juice | G3: 2 | H3: Passion fruit purée | I3: 0.75 | J3: 0 | K3: 0 | L3: Kombucha + tangerine + passion fruit over ice, fresh lime squeeze (Assumptions B113), slapped mint or basil leaf; pours from the kombucha keg. | M3: Vodka | N3: =B3*Assumptions!$B$39*Assumptions!$B$40
A4: Michelada (built) | B4: =Assumptions!$B$60 | C4: =B4/$B$19 | D4: Mexican Lager keg | E4: 8 | F4: Clamato | G4: 4 | H4: Lime juice (fresh) | I4: 0.5 | J4: 0 | K4: 0 | L4: Chelada built to order off the Mexican Lager keg: Clamato + fresh lime + hot sauce, Tajin rim. Extras itemized on Other Consumables rows 38-41. | N4: 0
A5: Vanilla Cherry Grove | B5: 120 | C5: =B5/$B$19 | D5: Coke | E5: 4 | F5: Vanilla | G5: 0.5 | H5: Cherry | I5: 0.5 | J5: 0.5 | K5: 0 | M5: Bourbon | N5: =B5*Assumptions!$B$39*Assumptions!$B$40
A6: Orange Cream-sicle | B6: 60 | C6: =B6/$B$19 | D6: Orange Fanta | E6: 4 | G6: 0 | I6: 0 | J6: 1 | K6: 1 | M6: Vodka | N6: =B6*Assumptions!$B$39*Assumptions!$B$40
A7: Watermelon Sugar High | B7: 50 | C7: =B7/$B$19 | D7: Lemonade | E7: 4 | F7: Watermelon | G7: 1 | I7: 0 | J7: 1 | K7: 0 | L7: Muddled fresh mint | M7: Blanco Tequila | N7: =B7*Assumptions!$B$39*Assumptions!$B$40
A8: A Ginger's Pickle (Big Dill Energy) | B8: 40 | C8: =B8/$B$19 | D8: Ginger ale | E8: 4 | G8: 0 | I8: 0 | J8: 1 | K8: 0 | L8: Pickle juice 0.5oz + Tajin rim | M8: Whiskey | N8: =B8*Assumptions!$B$39*Assumptions!$B$40
A9: The Dr's Cream | B9: 70 | C9: =B9/$B$19 | D9: Dr Pepper | E9: 4 | F9: Vanilla | G9: 1 | I9: 0 | J9: 0.5 | K9: 0.5 | M9: Bourbon | N9: =B9*Assumptions!$B$39*Assumptions!$B$40
A10: The Dr's Peach Exam | B10: 50 | C10: =B10/$B$19 | D10: Dr Pepper | E10: 4 | F10: Vanilla | G10: 0.5 | H10: Peach | I10: 0.5 | J10: 0.5 | K10: 0.5 | M10: Whiskey | N10: =B10*Assumptions!$B$39*Assumptions!$B$40 | O10: Needs soda water
A11: SCoBY-Dew / ScoBY-Mexican-Mule | B11: 40 | C11: =B11/$B$19 | D11: Kombucha keg | E11: 4 | F11: Lemon juice (fresh) | G11: 0.5 | H11: Ginger beer | I11: 3 | J11: 0 | K11: 0 | L11: Fresh lemon juice + agave + apple cider vinegar + ginger beer over kombucha pulled from the keg. Per-serving amounts for the simple syrup, ACV and agave live on Assumptions B98/B128/B131; everything is itemized on Other Consumables rows 35-37 and 45-46. | M11: Vodka | N11: =B11*Assumptions!$B$39*Assumptions!$B$40
A12: Thirst Trap | B12: 50 | C12: =B12/$B$19 | D12: Squirt | E12: 4 | F12: Cucumber | G12: 0.75 | H12: Lime juice (fresh) | I12: 0.5 | J12: 2 | K12: 0 | L12: Muddle the cucumber, then Squirt + soda water over ice. Two-finger pinch of salt or a Tajin rim — the salt is what kills the grapefruit bitterness. | M12: Blanco Tequila | N12: =B12*Assumptions!$B$39*Assumptions!$B$40
A13: Sakura Kisses (SAT ONLY reveal) | B13: 33 | C13: =B13/$B$19 | D13: Green tea keg | E13: 4 | F13: Orange juice | G13: 2 | H13: Sakura syrup | I13: 0.5 | J13: 0 | K13: 0 | L13: SATURDAY ONLY — Catboy Café finale, built to order off the green tea keg (replaces the retired Saturday aqua fresca jug). Green tea over ice + orange juice + sakura syrup, plus orange syrup and passion fruit purée (Assumptions B118); mint or cucumber garnish. | N13: 0
A14: Clear Cache (built) — Clear Mind keg | B14: 40 | C14: =B14/$B$19 | D14: Kombucha keg (Clear Mind) | E14: 4 | F14: Peach | G14: 0.5 | H14: Lemon juice (fresh) | I14: 0.5 | J14: 1 | K14: 0 | L14: Built off the Brew Dr. Clear Mind keg (rosemary, mint, sage, green tea). Kombucha over ice + peach syrup + fresh lemon, topped with soda water. Slap a fresh sage leaf and drop it in; pinch of salt. Peach + green tea is the classic pairing, sage is the twist, and the kombucha's acidity keeps the peach from reading as candy. | M14: Bourbon | N14: =B14*Assumptions!$B$39*Assumptions!$B$40
A15: Catboy Snot (SAT ONLY reveal) | B15: 25 | C15: =B15/$B$19 | D15: Squirt | E15: 4 | F15: Melon | G15: 0.5 | H15: Lime juice (fresh) | I15: 0.5 | J15: 0 | K15: 0 | L15: SATURDAY ONLY — Catboy Café finale, do not put it on the board before Saturday. Squirt + melon syrup + fresh lime over ice, then 2 oz of aloe vera juice WITH THE PULP spooned in (per-serving oz on Assumptions B147) so the cubes hang in suspension — that is the whole gag. Two-finger pinch of salt, same as Thirst Trap: the salt is what kills the grapefruit bitterness. Tint the ALOE BOTTLE (not the cup) with a pinch of the blue spirulina already bought for Blue Screen of Death — pale-yellow Squirt + blue reads green, and tinting per-cup comes out uneven. Optional basil seeds (Assumptions B150), hydrated in water ahead of service. BUY DRINKING ALOE — inner-fillet/decolorized, NOT whole-leaf or supplement aloe (aloin = laxative). | M15: Blanco Tequila | N15: =B15*Assumptions!$B$39*Assumptions!$B$40
A16: Catboy Piss (SAT ONLY reveal) | B16: 25 | C16: =B16/$B$19 | D16: Red Bull | E16: 4 | F16: Passion fruit purée | G16: 0.5 | H16: Lime juice (fresh) | I16: 0.5 | J16: 0 | K16: 0 | L16: SATURDAY ONLY — do not put it on the board before Saturday. Red Bull + blanco tequila over ice, passion fruit purée and fresh lime, Tajin rim. The purée deepens the colour to a genuinely alarming gold and its tartness cuts the Red Bull sweetness; the salty-spicy rim is what stops it tasting like a dorm drink. Red Bull comes off the Bar Add-Ons tab (12 of the 24 cans). | M16: Blanco Tequila | N16: =B16*Assumptions!$B$39*Assumptions!$B$40
A17: Shirley Temple of Doom | B17: 25 | C17: =B17/$B$19 | D17: Sprite | E17: 3 | F17: Cherry | G17: 0.75 | H17: Lime juice (fresh) | I17: 0.5 | J17: 2 | K17: 0 | L17: Sprite + cherry syrup + fresh lime over ice, topped with soda water. TAJIN RIM plus a two-finger pinch of salt — cherry + chile-lime is chamoy logic, and the salt and acid are what stop it reading as candy in the heat. Same rim station as the Michelada, A Ginger's Pickle and Catboy Piss, so it adds no new workflow. No coconut cream (it was pulled from the plain Shirley Temple on row 6 as well). | M17: Vodka | N17: =B17*Assumptions!$B$39*Assumptions!$B$40
A18: Shirley Mule | B18: 10 | C18: =B18/$B$19 | D18: Ginger ale | E18: 3 | F18: Cherry | G18: 0.75 | H18: Ginger beer | I18: 2 | J18: 0 | K18: 0 | L18: Ginger ale + ginger beer + cherry syrup over ice, plus a 0.5 oz fresh lime squeeze (Assumptions B154 — the two ingredient slots here are full, same situation as Tang Dynasty). Ginger is genuinely useful for dust-and-heat stomach and the ginger beer's bite cuts the cherry. Vodka is the default; whiskey works too. Ginger beer is sized on Other Consumables row 36; the Bar Add-Ons buffer covers overflow. | M18: Vodka | N18: =B18*Assumptions!$B$39*Assumptions!$B$40
A19: TOTAL DIRTY-SODA SERVINGS | B19: =SUM(B3:B18) | N19: =SUM(N3:N18)

Sheet Kegs
A1: Fixed Kegs — finished beverages on tap
A3: Each keg is a finished drink poured straight (plus optional add-ons). Servings/keg and price come from Assumptions. The kombucha kegs also feed two built drinks (Kombucha Mule + Tang Dynasty) and the Mexican Lager keg feeds the built Michelada — those servings are subtracted from the keg counts here so nothing is double-counted. Two continuous tap lines run all week; see the Keg Rotation tab for the day-by-day lineup.
A5: Keg | B5: # kegs | C5: Servings | D5: Keg $/ea | E5: Add-ons / garnish ideas | F5: Subtotal
A6: Cider | B6: 1 | C6: =B6*Assumptions!$B$12 | D6: =Assumptions!$B$24 | E6: Sun-Mon on the 'other tap' line, opening with the Sunday party. Cinnamon-sugar rim, apple/pear slice, orange squeeze, rosemary/thyme sprig, candied ginger, pomegranate float | F6: =B6*(D6+Assumptions!$B$28)
A7: Kombucha (passionfruit) | B7: 2 | C7: =B7*Assumptions!$B$12-Recipes!$B$11-Recipes!$B$3 | D7: =Assumptions!$B$25 | E7: Tue-Fri on the 'other tap' line. Two kegs, 150 pours: 40 Tang Dynasty + 40 SCOBY-Dew + the rest straight. SCOBY-Dew can equally be pulled from the Clear Mind keg — it is netted out here only so the maths has one home. Tang Dynasty should always come off THIS keg (passionfruit). | F7: =B7*(D7+Assumptions!$B$28)
A8: Ancho Paloma Sour Ale | B8: 1 | C8: =B8*Assumptions!$B$12 | D8: =Assumptions!$B$58 | E8: Sunday party + Mon-Tue on the beer line; served straight, grapefruit wheel garnish. | F8: =B8*(D8+Assumptions!$B$28)
A9: Green tea | B9: 1 | C9: =B9*Assumptions!$B$12-Recipes!$B$13 | D9: =Assumptions!$B$27 | E9: Saturday on the 'other tap' line — Catboy Café finale. The keg's 50 pours split 33 built Catboy Café Green Tea (Recipes row 14) + the remainder poured straight as the Green Tea Refresher: aloe vera drink + tea, optional lychee + syrup, mint, cucumber, yuzu/lemon, honey, agar boba. The built servings are netted out here so they aren't double-counted. | F9: =B9*(D9+Assumptions!$B$28)+Assumptions!$B$63*Assumptions!$B$62
A10: Biggest Little Blonde Ale | B10: 1 | C10: =B10*Assumptions!$B$66 | D10: =Assumptions!$B$59*Assumptions!$B$65 | E10: Closes out the beer line Fri-Sat (half keg). | F10: =B10*(D10+Assumptions!$B$28)
A11: Mexican Lager | B11: 1 | C11: =B11*Assumptions!$B$12-Recipes!$B$4 | D11: =Assumptions!$B$67 | E11: Wed-Thu on the beer line. Splits 30 built Micheladas (chelada mix, Tajin rim, lime, Clamato) + 20 straight pours; the Michelada servings are netted out of this row so they aren't double-counted against the Recipes tab. | F11: =B11*(D11+Assumptions!$B$28)
A12: Kombucha (Clear Mind) | B12: 1 | C12: =B12*Assumptions!$B$12-Recipes!$B$14 | D12: =Assumptions!$B$145 | E12: Brew Dr. Clear Mind — rosemary, mint, sage, green tea. Feeds the built Clear Cache (peach + lemon + sage); remainder poured straight. Herbaceous and savoury, so keep Tang Dynasty's passionfruit off this one — sage and passionfruit clash. | F12: =B12*(D12+Assumptions!$B$28)
A13: TOTAL KEGS | B13: =SUM(B6:B12) | C13: =SUM(C6:C12) | F13: =SUM(F6:F12)

Sheet Base Soda — Cans
A1: Base Soda Requirement → Cans & Cases
A3: Base soda | B3: Total oz | C3: +buffer | D3: Cans | E3: Cases | F3: Note
A4: Sprite | B4: =SUMPRODUCT((Recipes!$D$3:$D$18=A4)*Recipes!$E$3:$E$18*Recipes!$B$3:$B$18)+SUMPRODUCT((Recipes!$D$3:$D$18="Squirt")*2*Recipes!$B$3:$B$18)+SUMPRODUCT(('Daily Schedule'!$F$4:$F$15="Sprite")*'Daily Schedule'!$G$4:$G$15)+SUMPRODUCT(('Daily Schedule'!$H$4:$H$15="Sprite")*'Daily Schedule'!$I$4:$I$15)+SUMPRODUCT(('Daily Schedule'!$J$4:$J$15="Sprite")*'Daily Schedule'!$K$4:$K$15)+SUMPRODUCT(('Daily Schedule'!$L$4:$L$15="Sprite")*'Daily Schedule'!$M$4:$M$15)+SUMPRODUCT(('Daily Schedule'!$N$4:$N$15="Sprite")*'Daily Schedule'!$O$4:$O$15) | C4: =B4*(1+Assumptions!$B$5) | D4: =CEILING(C4/Assumptions!$B$7,1) | E4: =CEILING(D4/Assumptions!$B$6,1)
A5: Coke | B5: =SUMPRODUCT((Recipes!$D$3:$D$18=A5)*Recipes!$E$3:$E$18*Recipes!$B$3:$B$18) | C5: =B5*(1+Assumptions!$B$5) | D5: =CEILING(C5/Assumptions!$B$7,1) | E5: =CEILING(D5/Assumptions!$B$6,1)
A6: Orange Fanta | B6: =SUMPRODUCT((Recipes!$D$3:$D$18=A6)*Recipes!$E$3:$E$18*Recipes!$B$3:$B$18) | C6: =B6*(1+Assumptions!$B$5) | D6: =CEILING(C6/Assumptions!$B$7,1) | E6: =CEILING(D6/Assumptions!$B$6,1)
A7: Lemonade | B7: =SUMPRODUCT((Recipes!$D$3:$D$18=A7)*Recipes!$E$3:$E$18*Recipes!$B$3:$B$18) | C7: =B7*(1+Assumptions!$B$5) | D7: =CEILING(C7/Assumptions!$B$7,1) | E7: =CEILING(D7/Assumptions!$B$6,1) | F7: Mixed/priced separately
A8: Dr Pepper | B8: =SUMPRODUCT((Recipes!$D$3:$D$18=A8)*Recipes!$E$3:$E$18*Recipes!$B$3:$B$18) | C8: =B8*(1+Assumptions!$B$5) | D8: =CEILING(C8/Assumptions!$B$7,1) | E8: =CEILING(D8/Assumptions!$B$6,1)
A9: Ginger ale | B9: =SUMPRODUCT((Recipes!$D$3:$D$18=A9)*Recipes!$E$3:$E$18*Recipes!$B$3:$B$18) | C9: =B9*(1+Assumptions!$B$5) | D9: =CEILING(C9/Assumptions!$B$7,1) | E9: =CEILING(D9/Assumptions!$B$6,1)
A10: Squirt | B10: =SUMPRODUCT((Recipes!$D$3:$D$18=A10)*Recipes!$E$3:$E$18*Recipes!$B$3:$B$18) | C10: =B10*(1+Assumptions!$B$5) | D10: =CEILING(C10/Assumptions!$B$7,1) | E10: =CEILING(D10/Assumptions!$B$6,1)
A11: Horchata mix | B11: =SUMPRODUCT((Recipes!$D$3:$D$18=A11)*Recipes!$E$3:$E$18*Recipes!$B$3:$B$18)+SUMPRODUCT(('Daily Schedule'!$F$4:$F$15="Horchata mix")*'Daily Schedule'!$G$4:$G$15)+SUMPRODUCT(('Daily Schedule'!$H$4:$H$15="Horchata mix")*'Daily Schedule'!$I$4:$I$15)+SUMPRODUCT(('Daily Schedule'!$J$4:$J$15="Horchata mix")*'Daily Schedule'!$K$4:$K$15)+SUMPRODUCT(('Daily Schedule'!$L$4:$L$15="Horchata mix")*'Daily Schedule'!$M$4:$M$15)+SUMPRODUCT(('Daily Schedule'!$N$4:$N$15="Horchata mix")*'Daily Schedule'!$O$4:$O$15) | C11: =B11*(1+Assumptions!$B$5) | D11: =CEILING(C11/Assumptions!$B$7,1) | E11: =CEILING(D11/Assumptions!$B$6,1) | F11: Mixed/priced separately
A12: Mountain Dew | B12: =SUMPRODUCT((Recipes!$D$3:$D$18=A12)*Recipes!$E$3:$E$18*Recipes!$B$3:$B$18)+SUMPRODUCT(('Daily Schedule'!$F$4:$F$15="Mountain Dew")*'Daily Schedule'!$G$4:$G$15)+SUMPRODUCT(('Daily Schedule'!$H$4:$H$15="Mountain Dew")*'Daily Schedule'!$I$4:$I$15)+SUMPRODUCT(('Daily Schedule'!$J$4:$J$15="Mountain Dew")*'Daily Schedule'!$K$4:$K$15)+SUMPRODUCT(('Daily Schedule'!$L$4:$L$15="Mountain Dew")*'Daily Schedule'!$M$4:$M$15)+SUMPRODUCT(('Daily Schedule'!$N$4:$N$15="Mountain Dew")*'Daily Schedule'!$O$4:$O$15) | C12: =B12*(1+Assumptions!$B$5) | D12: =CEILING(C12/Assumptions!$B$7,1) | E12: =CEILING(D12/Assumptions!$B$6,1) | F12: Daily special (Tue Baja Blast)
A13: TOTAL | B13: =SUM(B4:B12) | C13: =SUM(C4:C12) | D13: =SUM(D4:D12) | E13: =SUM(E4:E12)

Sheet Other Consumables
A1: Other Consumables — syrups, cream, dairy, garnish
A3: SYRUPS
A4: Syrup | B4: Total oz | C4: +buffer | D4: Bottles | E4: Note
A5: Peach | B5: =SUMPRODUCT((Recipes!$F$3:$F$18=A5)*Recipes!$G$3:$G$18*Recipes!$B$3:$B$18)+SUMPRODUCT((Recipes!$H$3:$H$18=A5)*Recipes!$I$3:$I$18*Recipes!$B$3:$B$18)+SUMPRODUCT(('Daily Schedule'!$F$4:$F$15="Peach syrup")*'Daily Schedule'!$G$4:$G$15)+SUMPRODUCT(('Daily Schedule'!$H$4:$H$15="Peach syrup")*'Daily Schedule'!$I$4:$I$15)+SUMPRODUCT(('Daily Schedule'!$J$4:$J$15="Peach syrup")*'Daily Schedule'!$K$4:$K$15)+SUMPRODUCT(('Daily Schedule'!$L$4:$L$15="Peach syrup")*'Daily Schedule'!$M$4:$M$15)+SUMPRODUCT(('Daily Schedule'!$N$4:$N$15="Peach syrup")*'Daily Schedule'!$O$4:$O$15) | C5: =B5*(1+Assumptions!$B$5) | D5: =CEILING(C5/Assumptions!$B$8,1) | E5: Torani 750ml
A6: Pineapple | B6: =SUMPRODUCT((Recipes!$F$3:$F$18=A6)*Recipes!$G$3:$G$18*Recipes!$B$3:$B$18)+SUMPRODUCT((Recipes!$H$3:$H$18=A6)*Recipes!$I$3:$I$18*Recipes!$B$3:$B$18)+SUMPRODUCT(('Daily Schedule'!$F$4:$F$15="Pineapple syrup")*'Daily Schedule'!$G$4:$G$15)+SUMPRODUCT(('Daily Schedule'!$H$4:$H$15="Pineapple syrup")*'Daily Schedule'!$I$4:$I$15)+SUMPRODUCT(('Daily Schedule'!$J$4:$J$15="Pineapple syrup")*'Daily Schedule'!$K$4:$K$15)+SUMPRODUCT(('Daily Schedule'!$L$4:$L$15="Pineapple syrup")*'Daily Schedule'!$M$4:$M$15)+SUMPRODUCT(('Daily Schedule'!$N$4:$N$15="Pineapple syrup")*'Daily Schedule'!$O$4:$O$15) | C6: =B6*(1+Assumptions!$B$5) | D6: =CEILING(C6/Assumptions!$B$8,1) | E6: Torani 750ml
A7: Vanilla | B7: =SUMPRODUCT((Recipes!$F$3:$F$18=A7)*Recipes!$G$3:$G$18*Recipes!$B$3:$B$18)+SUMPRODUCT((Recipes!$H$3:$H$18=A7)*Recipes!$I$3:$I$18*Recipes!$B$3:$B$18)+SUMPRODUCT(('Daily Schedule'!$F$4:$F$15="Vanilla syrup")*'Daily Schedule'!$G$4:$G$15)+SUMPRODUCT(('Daily Schedule'!$H$4:$H$15="Vanilla syrup")*'Daily Schedule'!$I$4:$I$15)+SUMPRODUCT(('Daily Schedule'!$J$4:$J$15="Vanilla syrup")*'Daily Schedule'!$K$4:$K$15)+SUMPRODUCT(('Daily Schedule'!$L$4:$L$15="Vanilla syrup")*'Daily Schedule'!$M$4:$M$15)+SUMPRODUCT(('Daily Schedule'!$N$4:$N$15="Vanilla syrup")*'Daily Schedule'!$O$4:$O$15) | C7: =B7*(1+Assumptions!$B$5) | D7: =CEILING(C7/Assumptions!$B$8,1) | E7: Torani 750ml
A8: Cherry | B8: =SUMPRODUCT((Recipes!$F$3:$F$18=A8)*Recipes!$G$3:$G$18*Recipes!$B$3:$B$18)+SUMPRODUCT((Recipes!$H$3:$H$18=A8)*Recipes!$I$3:$I$18*Recipes!$B$3:$B$18)+SUMPRODUCT(('Daily Schedule'!$F$4:$F$15="Cherry syrup")*'Daily Schedule'!$G$4:$G$15)+SUMPRODUCT(('Daily Schedule'!$H$4:$H$15="Cherry syrup")*'Daily Schedule'!$I$4:$I$15)+SUMPRODUCT(('Daily Schedule'!$J$4:$J$15="Cherry syrup")*'Daily Schedule'!$K$4:$K$15)+SUMPRODUCT(('Daily Schedule'!$L$4:$L$15="Cherry syrup")*'Daily Schedule'!$M$4:$M$15)+SUMPRODUCT(('Daily Schedule'!$N$4:$N$15="Cherry syrup")*'Daily Schedule'!$O$4:$O$15) | C8: =B8*(1+Assumptions!$B$5) | D8: =CEILING(C8/Assumptions!$B$8,1) | E8: Torani 750ml
A9: Watermelon | B9: =SUMPRODUCT((Recipes!$F$3:$F$18=A9)*Recipes!$G$3:$G$18*Recipes!$B$3:$B$18)+SUMPRODUCT((Recipes!$H$3:$H$18=A9)*Recipes!$I$3:$I$18*Recipes!$B$3:$B$18)+SUMPRODUCT(('Daily Schedule'!$F$4:$F$15="Watermelon syrup")*'Daily Schedule'!$G$4:$G$15)+SUMPRODUCT(('Daily Schedule'!$H$4:$H$15="Watermelon syrup")*'Daily Schedule'!$I$4:$I$15)+SUMPRODUCT(('Daily Schedule'!$J$4:$J$15="Watermelon syrup")*'Daily Schedule'!$K$4:$K$15)+SUMPRODUCT(('Daily Schedule'!$L$4:$L$15="Watermelon syrup")*'Daily Schedule'!$M$4:$M$15)+SUMPRODUCT(('Daily Schedule'!$N$4:$N$15="Watermelon syrup")*'Daily Schedule'!$O$4:$O$15) | C9: =B9*(1+Assumptions!$B$5) | D9: =CEILING(C9/Assumptions!$B$8,1) | E9: Torani 750ml
A10: Melon | B10: =SUMPRODUCT((Recipes!$F$3:$F$18=A10)*Recipes!$G$3:$G$18*Recipes!$B$3:$B$18)+SUMPRODUCT((Recipes!$H$3:$H$18=A10)*Recipes!$I$3:$I$18*Recipes!$B$3:$B$18) | C10: =B10*(1+Assumptions!$B$5) | D10: =CEILING(C10/Assumptions!$B$8,1) | E10: Torani 750ml — green melon (midori-style). Catboy Snot + a 6th Italian-soda flavour.
A11: Lemon | B11: =SUMPRODUCT((Recipes!$F$3:$F$18=A11)*Recipes!$G$3:$G$18*Recipes!$B$3:$B$18)+SUMPRODUCT((Recipes!$H$3:$H$18=A11)*Recipes!$I$3:$I$18*Recipes!$B$3:$B$18)+SUMPRODUCT(('Daily Schedule'!$F$4:$F$15="Lemon syrup")*'Daily Schedule'!$G$4:$G$15)+SUMPRODUCT(('Daily Schedule'!$H$4:$H$15="Lemon syrup")*'Daily Schedule'!$I$4:$I$15)+SUMPRODUCT(('Daily Schedule'!$J$4:$J$15="Lemon syrup")*'Daily Schedule'!$K$4:$K$15)+SUMPRODUCT(('Daily Schedule'!$L$4:$L$15="Lemon syrup")*'Daily Schedule'!$M$4:$M$15)+SUMPRODUCT(('Daily Schedule'!$N$4:$N$15="Lemon syrup")*'Daily Schedule'!$O$4:$O$15) | C11: =B11*(1+Assumptions!$B$5) | D11: =CEILING(C11/Assumptions!$B$8,1) | E11: Torani 750ml
A12: TOTAL | B12: =SUM(B5:B11) | C12: =SUM(C5:C11) | D12: =SUM(D5:D11)
A14: CREAM, DAIRY & NON-CANNED BASES
A15: Item | B15: Total oz | C15: +buffer | D15: Units | E15: Unit/note
A16: Cream of coconut | B16: =SUMPRODUCT(Recipes!$K$3:$K$18*Recipes!$B$3:$B$18)+SUMPRODUCT(('Daily Schedule'!$F$4:$F$15="Coconut cream")*'Daily Schedule'!$G$4:$G$15)+SUMPRODUCT(('Daily Schedule'!$H$4:$H$15="Coconut cream")*'Daily Schedule'!$I$4:$I$15)+SUMPRODUCT(('Daily Schedule'!$J$4:$J$15="Coconut cream")*'Daily Schedule'!$K$4:$K$15)+SUMPRODUCT(('Daily Schedule'!$L$4:$L$15="Coconut cream")*'Daily Schedule'!$M$4:$M$15)+SUMPRODUCT(('Daily Schedule'!$N$4:$N$15="Coconut cream")*'Daily Schedule'!$O$4:$O$15) | C16: =B16*(1+Assumptions!$B$5) | D16: =CEILING(C16/Assumptions!$B$9,1) | E16: 22oz squeeze bottles (Amazon)
A17: Passion fruit purée | B17: =SUMPRODUCT((Recipes!$F$3:$F$18=A17)*Recipes!$G$3:$G$18*Recipes!$B$3:$B$18)+SUMPRODUCT((Recipes!$H$3:$H$18=A17)*Recipes!$I$3:$I$18*Recipes!$B$3:$B$18)+SUMPRODUCT(('Daily Schedule'!$F$4:$F$15="Passion fruit purée")*'Daily Schedule'!$G$4:$G$15)+SUMPRODUCT(('Daily Schedule'!$H$4:$H$15="Passion fruit purée")*'Daily Schedule'!$I$4:$I$15)+SUMPRODUCT(('Daily Schedule'!$J$4:$J$15="Passion fruit purée")*'Daily Schedule'!$K$4:$K$15)+SUMPRODUCT(('Daily Schedule'!$L$4:$L$15="Passion fruit purée")*'Daily Schedule'!$M$4:$M$15)+SUMPRODUCT(('Daily Schedule'!$N$4:$N$15="Passion fruit purée")*'Daily Schedule'!$O$4:$O$15)+Recipes!$B$13*Assumptions!$B$118 | C17: =B17*(1+Assumptions!$B$5) | D17: =CEILING(C17/Assumptions!$B$91,1) | E17: 22oz squeeze bottles (Amazon)
A18: Pineapple purée | B18: =SUMPRODUCT((Recipes!$F$3:$F$18=A18)*Recipes!$G$3:$G$18*Recipes!$B$3:$B$18)+SUMPRODUCT((Recipes!$H$3:$H$18=A18)*Recipes!$I$3:$I$18*Recipes!$B$3:$B$18)+SUMPRODUCT(('Daily Schedule'!$F$4:$F$15="Pineapple purée")*'Daily Schedule'!$G$4:$G$15)+SUMPRODUCT(('Daily Schedule'!$H$4:$H$15="Pineapple purée")*'Daily Schedule'!$I$4:$I$15)+SUMPRODUCT(('Daily Schedule'!$J$4:$J$15="Pineapple purée")*'Daily Schedule'!$K$4:$K$15)+SUMPRODUCT(('Daily Schedule'!$L$4:$L$15="Pineapple purée")*'Daily Schedule'!$M$4:$M$15)+SUMPRODUCT(('Daily Schedule'!$N$4:$N$15="Pineapple purée")*'Daily Schedule'!$O$4:$O$15) | C18: =B18*(1+Assumptions!$B$5) | D18: =CEILING(C18/Assumptions!$B$91,1) | E18: 22oz squeeze bottles (Amazon)
A19: Lemonade (base) | B19: =SUMPRODUCT((Recipes!$D$3:$D$18="Lemonade")*Recipes!$E$3:$E$18*Recipes!$B$3:$B$18)+SUMPRODUCT(('Daily Schedule'!$F$4:$F$15="Lemonade")*'Daily Schedule'!$G$4:$G$15)+SUMPRODUCT(('Daily Schedule'!$H$4:$H$15="Lemonade")*'Daily Schedule'!$I$4:$I$15)+SUMPRODUCT(('Daily Schedule'!$J$4:$J$15="Lemonade")*'Daily Schedule'!$K$4:$K$15)+SUMPRODUCT(('Daily Schedule'!$L$4:$L$15="Lemonade")*'Daily Schedule'!$M$4:$M$15)+SUMPRODUCT(('Daily Schedule'!$N$4:$N$15="Lemonade")*'Daily Schedule'!$O$4:$O$15) | C19: =B19*(1+Assumptions!$B$5) | D19: =CEILING(C19/128,1) | E19: gallons
A20: Soda water | B20: =SUMPRODUCT(Recipes!$J$3:$J$18*Recipes!$B$3:$B$18)+SUMPRODUCT(('Daily Schedule'!$F$4:$F$15="Soda water")*'Daily Schedule'!$G$4:$G$15)+SUMPRODUCT(('Daily Schedule'!$H$4:$H$15="Soda water")*'Daily Schedule'!$I$4:$I$15)+SUMPRODUCT(('Daily Schedule'!$J$4:$J$15="Soda water")*'Daily Schedule'!$K$4:$K$15)+SUMPRODUCT(('Daily Schedule'!$L$4:$L$15="Soda water")*'Daily Schedule'!$M$4:$M$15)+SUMPRODUCT(('Daily Schedule'!$N$4:$N$15="Soda water")*'Daily Schedule'!$O$4:$O$15) | C20: =B20*(1+Assumptions!$B$5) | D20: =CEILING(C20/Assumptions!$B$7,1) | E20: 12 oz cans
A21: Tangerine juice | B21: =SUMPRODUCT((Recipes!$F$3:$F$18="Tangerine juice")*Recipes!$G$3:$G$18*Recipes!$B$3:$B$18)+SUMPRODUCT((Recipes!$H$3:$H$18="Tangerine juice")*Recipes!$I$3:$I$18*Recipes!$B$3:$B$18) | C21: =B21*(1+Assumptions!$B$5) | D21: =CEILING(C21/Assumptions!$B$89,1) | E21: 52oz bottles
A22: Garnish/misc: fresh mint & basil, limes, pickle juice + Tajín, cinnamon (horchata), ice, cups, straws. Keg add-ons priced on Kegs tab.
A24: LIQUOR (OPTIONAL ADD-ON)
A25: Liquor | B25: Total oz | C25: +buffer | D25: Bottles | E25: $/bottle | F25: Subtotal | G25: Note
A26: Vodka | B26: =SUMPRODUCT((Recipes!$M$3:$M$18=A26)*Recipes!$N$3:$N$18)+SUMPRODUCT(('Daily Schedule'!$P$4:$P$15=A26)*'Daily Schedule'!$R$4:$R$15) | C26: =B26*(1+Assumptions!$B$5) | D26: =CEILING(C26/Assumptions!$B$41,1) | E26: =Assumptions!$B$42 | F26: =D26*E26 | G26: Consider peach/vanilla flavored vodka for Peaches & Creamed / Orange Cream-sicle.
A27: Coconut Rum | B27: =SUMPRODUCT((Recipes!$M$3:$M$18=A27)*Recipes!$N$3:$N$18)+SUMPRODUCT(('Daily Schedule'!$P$4:$P$15=A27)*'Daily Schedule'!$R$4:$R$15) | C27: =B27*(1+Assumptions!$B$5) | D27: =CEILING(C27/Assumptions!$B$41,1) | E27: =Assumptions!$B$43 | F27: =D27*E27
A28: Bourbon | B28: =SUMPRODUCT((Recipes!$M$3:$M$18=A28)*Recipes!$N$3:$N$18)+SUMPRODUCT(('Daily Schedule'!$P$4:$P$15=A28)*'Daily Schedule'!$R$4:$R$15) | C28: =B28*(1+Assumptions!$B$5) | D28: =CEILING(C28/Assumptions!$B$41,1) | E28: =Assumptions!$B$44 | F28: =D28*E28
A29: Blanco Tequila | B29: =SUMPRODUCT((Recipes!$M$3:$M$18=A29)*Recipes!$N$3:$N$18)+SUMPRODUCT(('Daily Schedule'!$P$4:$P$15=A29)*'Daily Schedule'!$R$4:$R$15) | C29: =B29*(1+Assumptions!$B$5) | D29: =CEILING(C29/Assumptions!$B$41,1) | E29: =Assumptions!$B$45 | F29: =D29*E29
A30: Spiced Rum | B30: =SUMPRODUCT((Recipes!$M$3:$M$18=A30)*Recipes!$N$3:$N$18)+SUMPRODUCT(('Daily Schedule'!$P$4:$P$15=A30)*'Daily Schedule'!$R$4:$R$15) | C30: =B30*(1+Assumptions!$B$5) | D30: =CEILING(C30/Assumptions!$B$41,1) | E30: =Assumptions!$B$46 | F30: =D30*E30
A31: Whiskey | B31: =SUMPRODUCT((Recipes!$M$3:$M$18=A31)*Recipes!$N$3:$N$18)+SUMPRODUCT(('Daily Schedule'!$P$4:$P$15=A31)*'Daily Schedule'!$R$4:$R$15) | C31: =B31*(1+Assumptions!$B$5) | D31: =CEILING(C31/Assumptions!$B$41,1) | E31: =Assumptions!$B$47 | F31: =D31*E31 | G31: Consider 1 pickle whiskey (e.g. Ole Smoky) for A Ginger's Pickle as a novelty side option.
A32: TOTAL | B32: =SUM(B26:B31) | C32: =SUM(C26:C31) | D32: =SUM(D26:D31) | F32: =SUM(F26:F31)
A34: BUILT-DRINK & FRESH-PRODUCE EXTRAS (itemized)
A35: Item | B35: Total oz | C35: +buffer | D35: Units | E35: Unit/note
A36: Ginger beer | B36: =(SUMPRODUCT((Recipes!$F$3:$F$18="Ginger beer")*Recipes!$G$3:$G$18*Recipes!$B$3:$B$18)+SUMPRODUCT((Recipes!$H$3:$H$18="Ginger beer")*Recipes!$I$3:$I$18*Recipes!$B$3:$B$18)) | C36: =B36*(1+Assumptions!$B$5) | D36: =CEILING(C36/Assumptions!$B$96,1) | E36: 12oz cans
A37: Lemon juice (fresh) | B37: =(SUMPRODUCT((Recipes!$F$3:$F$18="Lemon juice (fresh)")*Recipes!$G$3:$G$18*Recipes!$B$3:$B$18)+SUMPRODUCT((Recipes!$H$3:$H$18="Lemon juice (fresh)")*Recipes!$I$3:$I$18*Recipes!$B$3:$B$18)) | C37: =B37*(1+Assumptions!$B$5) | D37: =CEILING(C37/Assumptions!$B$99,1) | E37: whole lemons (~1.5oz juice each)
A38: Simple syrup (sugar) — RETIRED, agave now (row 46) | B38: =Recipes!$B$11*Assumptions!$B$98 | C38: =B38*(1+Assumptions!$B$5) | D38: =CEILING(C38/Assumptions!$B$56,1) | E38: Computes 0 while Assumptions B98 is zeroed
A39: Clamato | B39: =(SUMPRODUCT((Recipes!$F$3:$F$18="Clamato")*Recipes!$G$3:$G$18*Recipes!$B$3:$B$18)+SUMPRODUCT((Recipes!$H$3:$H$18="Clamato")*Recipes!$I$3:$I$18*Recipes!$B$3:$B$18)) | C39: =B39*(1+Assumptions!$B$5) | D39: =CEILING(C39/Assumptions!$B$103,1) | E39: 64oz bottles
A40: Lime juice (fresh) | B40: =Recipes!$B$4*Recipes!$I$4+Recipes!$B$3*Assumptions!$B$113 | C40: =B40*(1+Assumptions!$B$5) | D40: =CEILING(C40/Assumptions!$B$111,1) | E40: whole limes (~1oz juice each) — Michelada + Tang Dynasty only
A41: Hot sauce | B41: =Recipes!$B$4*Assumptions!$B$105 | C41: =B41*(1+Assumptions!$B$5) | D41: =CEILING(C41/Assumptions!$B$106,1) | E41: 12oz bottles
A42: Tajin (rim salt) | B42: =(Recipes!$B$4+Recipes!$B$8+Recipes!$B$16+Recipes!$B$17)*Assumptions!$B$108 | C42: =B42*(1+Assumptions!$B$5) | D42: =CEILING(C42/Assumptions!$B$109,1) | E42: 5oz shakers — Michelada, A Ginger's Pickle and Catboy Piss rims
A43: Orange juice (Catboy Café build) | B43: =(SUMPRODUCT((Recipes!$F$3:$F$18="Orange juice")*Recipes!$G$3:$G$18*Recipes!$B$3:$B$18)+SUMPRODUCT((Recipes!$H$3:$H$18="Orange juice")*Recipes!$I$3:$I$18*Recipes!$B$3:$B$18)) | C43: =B43*(1+Assumptions!$B$5) | D43: =CEILING(C43/Assumptions!$B$69,1) | E43: 64oz cartons — separate from the Thursday jug's OJ so the cost lands on the right line
A44: Cucumber (Thirst Trap) | B44: =Recipes!$B$12*Recipes!$G$12 | C44: =B44*(1+Assumptions!$B$5) | D44: =CEILING(C44/Assumptions!$B$122,1) | E44: whole cucumbers (~10oz each, ~2-3 slices per drink)
...

Sheet Purchase List
A1: Purchase List — Burning Man 2026 Dirty Soda Bar
A3: Quantities pull live from the model. Fill Source/Location, then check off as you buy.
A4: ✓ | B4: Item | C4: Category | D4: Qty | E4: Unit | F4: Est. $ | G4: Source / Location
A5: ☐ | B5: Canned base soda (Sprite/Coke/Fanta/Dr Pepper/Ginger ale/Squirt/Mtn Dew) | C5: Soda | D5: ='Base Soda — Cans'!E4+'Base Soda — Cans'!E5+'Base Soda — Cans'!E6+'Base Soda — Cans'!E8+'Base Soda — Cans'!E9+'Base Soda — Cans'!E10+'Base Soda — Cans'!E12 | E5: cases | F5: =D5*Assumptions!$B$16 | G5: BevMo/ Costco
A6: ☐ | B6: Lemonade (from concentrate) | C6: Soda | D6: ='Other Consumables'!D19 | E6: gallons | F6: =D6*Assumptions!$B$17 | G6: Amazon / CostCo | H6: Mixed from concentrate in TWO sessions, not daily: ~2 gal on arrival (Watermelon Sugar High + Tue Smoke Test), ~1 gal Saturday morning (Blue Screen of Death). Held in the two 1-gallon containers on Supplies row 24. Water margin confirmed fine; switch formats at Assumptions B17.
A7: ☐ | B7: Horchata mix / rice-milk base | C7: Soda | D7: ='Base Soda — Cans'!E11 | E7: case-equiv | F7: =D7*Assumptions!$B$18 | G7: Latino Grocery
A8: ☐ | B8: Soda water | C8: Soda | D8: =CEILING('Other Consumables'!D20/Assumptions!$B$6,1) | E8: cases | F8: =D8*Assumptions!$B$22 | G8: BevMo/ Costco
A9: ☐ | B9: Torani syrups (all flavors) | C9: Syrup | D9: ='Other Consumables'!$D$12 | E9: bottles | F9: =D9*Assumptions!$B$19 | G9: Restaurant Supply / Amazon | H9: Now includes the melon syrup for Catboy Snot (Other Consumables row 10)
A10: ☐ | B10: Cream of coconut (22oz squeeze bottles) | C10: Dairy/cream | D10: ='Other Consumables'!D16 | E10: bottles | F10: =D10*Assumptions!$B$20 | G10: Amazon
A11: ☐ | B11: Passion fruit purée (22oz squeeze) | C11: Syrup | D11: ='Other Consumables'!D17 | E11: bottles | F11: =D11*Assumptions!$B$92 | G11: Amazon | H11: Tang Dynasty + Malibu Sunrise + Catboy green tea
A12: ☐ | B12: Kombucha keg (passionfruit) | C12: Keg | D12: =Kegs!B7 | E12: kegs | F12: =D12*Assumptions!$B$25 | G12: Mike's Liquours
A13: ☐ | B13: Ancho Paloma Sour Ale keg | C13: Keg | D13: =Kegs!B8 | E13: kegs | F13: =D13*Assumptions!$B$58 | G13: Lead Dog Brewing (Reno)
A14: ☐ | B14: Green tea keg | C14: Keg | D14: =Kegs!B9 | E14: kegs | F14: =D14*Assumptions!$B$27 | G14: Mike's Liquours
A15: ☐ | B15: Aloe vera drinks (Green Tea Refresher) | C15: Keg add-on | D15: =Kegs!C9 | E15: servings | F15: =ROUND(D15*0.6,0) | G15: Asian Grocery
A16: ☐ | B16: Lychee (canned) + mint/cucumber/yuzu | C16: Keg add-on | D16: =Kegs!B9 | E16: keg-set | F16: =D16*Assumptions!$B$28 | G16: Asian Grocery
A17: ☐ | B17: Ginger beer (12oz cans) — Kombucha Mule | C17: Built drink | D17: ='Other Consumables'!D36 | E17: cans | F17: =D17*Assumptions!$B$97 | G17: Grocery / BevMo (Reno) | H17: Mule build — 3oz per serving (Recipes I12); Shirley Mule adds 2oz per serving (Recipes I19)
A18: ☐ | B18: CO2 refills | C18: Rental/gas | D18: =Assumptions!$B$36 | E18: fills | F18: =D18*Assumptions!$B$35 | G18: Mike's Liquors | H18: 10lb bottle; 2nd fill is insurance
A19: ☐ | B19: Keg deposits (REFUNDABLE) | C19: Deposit | D19: =Kegs!B13 | E19: kegs | F19: =D19*Assumptions!$B$32 | G19: Mike's / breweries | H19: Cash up front, returned with empties — not in cost model
A20: ☐ | B20: Double jockey box rental (2 taps, 12 days = 3x 4-day) | C20: Rental/gas | D20: =Assumptions!$B$34 | E20: rentals | F20: =D20*Assumptions!$B$33 | G20: Mike's Liquors | H20: $150 per 4-day period, without keg
A21: ☐ | B21: 19-gallon tubs (ice bath for the two live kegs) | C21: Hardware | D21: 2 | E21: tubs | F21: =D21*20 | G21: Mike's Liquors | H21: Purchase, $20 ea — kegs stay cool while jockey box does the chilling
A22: ☐ | B22: CO2 tank + regulator + keg couplers (w/ jockey rental) | C22: Rental/gas | D22: 1 | E22: set | F22: 0 | G22: Mike's Liquors | H22: CONFIRM included w/ rental; else coupler rent $25/ea, regulator $79. Match coupler type (D/S) to each keg!
A23: ☐ | B23: Jumper lines, spare washers, faucet wrench | C23: Rental/gas | D23: 1 | E23: set | F23: 20 | G23: Mike's Liquors | H23: Usually included; beer line $2.50/ft if extra runs needed
A24: ☐ | B24: Vodka (750ml bottles) | C24: Liquor | D24: ='Other Consumables'!D26 | E24: bottles | F24: ='Other Consumables'!F26 | G24: Costco | H24: Peach/Vanilla or plain
A25: ☐ | B25: Coconut Rum (750ml bottles) | C25: Liquor | D25: ='Other Consumables'!D27 | E25: bottles | F25: ='Other Consumables'!F27 | G25: Costco | H25: Malibu
A26: ☐ | B26: Bourbon (750ml bottles) | C26: Liquor | D26: ='Other Consumables'!D28 | E26: bottles | F26: ='Other Consumables'!F28 | G26: Costco
A27: ☐ | B27: Blanco Tequila (750ml bottles) | C27: Liquor | D27: ='Other Consumables'!D29 | E27: bottles | F27: ='Other Consumables'!F29 | G27: Costco
A28: ☐ | B28: Spiced Rum (750ml bottles) | C28: Liquor | D28: ='Other Consumables'!D30 | E28: bottles | F28: ='Other Consumables'!F30 | G28: Costco
A29: ☐ | B29: Whiskey (750ml bottles) | C29: Liquor | D29: ='Other Consumables'!D31 | E29: bottles | F29: ='Other Consumables'!F31 | G29: Costco | H29: 1 pickle flavored
A30: ☐ | B30: Tajin (rim salt) — Michelada + Ginger's Pickle | C30: Built drink | D30: ='Other Consumables'!D42 | E30: shakers | F30: =D30*Assumptions!$B$110 | G30: Latino Grocery | H30: Was a flat $20 set; now sized from every rimmed drink — Michelada, A Ginger's Pickle, Catboy Piss and Shirley Temple of Doom.
A31: ☐ | B31: Cider keg | C31: Keg | D31: =Kegs!B6 | E31: kegs | F31: =D31*Assumptions!$B$24 | G31: Lead Dog Brewing (Reno)
A32: ☐ | B32: Biggest Little Blonde Ale keg | C32: Keg | D32: =Kegs!B10 | E32: kegs | F32: =D32*Assumptions!$B$59*Assumptions!$B$65 | G32: Lead Dog Brewing (Reno)
A33: ☐ | B33: Mexican Lager keg | C33: Keg | D33: =Kegs!B11 | E33: kegs | F33: =D33*Assumptions!$B$67 | G33: Mike's Liquours
A34: ☐ | B34: Clamato (64oz bottles) — Michelada | C34: Built drink | D34: ='Other Consumables'!D39 | E34: bottles | F34: =D34*Assumptions!$B$104 | G34: Grocery / Latino Grocery | H34: Michelada build — 4oz per serving (Recipes G4)
A35: ☐ | B35: Watermelon (whole — blend & strain for Mon fresca) | C35: Daily Special | D35: ='Daily Schedule'!D18 | E35: melons | F35: ='Daily Schedule'!F18 | G35: Grocery (Reno) / Costco
A36: ☐ | B36: Agave syrup — jug frescas | C36: Daily Special | D36: ='Daily Schedule'!D19 | E36: bottles | F36: ='Daily Schedule'!F19 | G36: Grocery / Costco | H36: Mon Hard Reset + Wed Red Flag (Daily Schedule row 19)
A37: ☐ | B37: Sakura + orange syrup (Sat Catboy Café add-on) | C37: Built drink | D37: =Assumptions!$B$63 | E37: bottles | F37: =D37*Assumptions!$B$62 | G37: Asian Grocery / Amazon | H37: Sakura + orange syrup for the built Catboy Café Green Tea (Recipes row 14)
A38: ☐ | B38: Orange juice (64oz cartons) | C38: Daily Special | D38: ='Daily Schedule'!D23 | E38: cartons | F38: ='Daily Schedule'!F23 | G38: Costco / Grocery (Reno)
A39: ☐ | B39: Pineapple juice (46oz cans) | C39: Daily Special | D39: ='Daily Schedule'!D24 | E39: cans | F39: ='Daily Schedule'!F24 | G39: Costco / Grocery (Reno)
A40: ☐ | B40: Grenadine | C40: Daily Special | D40: ='Daily Schedule'!D25 | E40: bottles | F40: ='Daily Schedule'!F25 | G40: BevMo / Grocery
A41: ☐ | B41: Blue spirulina powder | C41: Daily Special | D41: ='Daily Schedule'!D26 | E41: jar | F41: ='Daily Schedule'!F26 | G41: Amazon | H41: DIY Baja Blast color (Tue)
...

Sheet Supplies
A1: Supplies — Non-Consumable Bar Equipment
A3: One-time gear, not consumed per-drink — pack it once, reuse every year. People bring their own cups, so no cups/straws here. Check off as you pack/buy.
A4: ✓ | B4: Item | C4: Qty | D4: Used For | E4: Source / Location
A5: ☐ | B5: Jigger (1oz/2oz) | C5: 3 | D5: Precise pours: syrups, pickle juice, fresh lemon juice on every built drink. | E5: Amazon / Restaurant Supply
A6: ☐ | B6: Bar spoon (long) | C6: 3 | D6: Stir/layer all soda builds; dissolve sugar in the Kombucha Mule. | E6: Amazon / Restaurant Supply
A7: ☐ | B7: Muddler | C7: 2 | D7: Watermelon Mint Lemonade (fresh mint); Kombucha Mule (lemon + sugar). | E7: Amazon / Restaurant Supply
A8: ☐ | B8: Whisk | C8: 2 | D8: Whore-chata (rice-milk base + cinnamon/vanilla syrup); smooth out coconut cream before batching. | E8: Camp kitchen (check first)
A9: ☐ | B9: Blender (12V or battery) | C9: 1 | D9: Blend watermelon (+mint) for the Monday fresca; froth coconut-cream builds. | E9: Amazon (playa-power 12V/battery)
A10: ☐ | B10: Cocktail shaker tin (Boston shaker) | C10: 2 | D10: Quick-shake creamy builds (Shirley got Creamed, Orange Cream-sicle, The Dr's Cream/Peach Exam) without tying up the blender. | E10: Amazon / Restaurant Supply
A11: ☐ | B11: Measuring cups (1-4 cup set) | C11: 2 | D11: Batch horchata base, lemonade, and cinnamon/vanilla syrup mix ahead of rush. | E11: Camp kitchen (check first)
A12: ☐ | B12: Citrus juicer/reamer | C12: 1 | D12: Fresh lemon juice for the Kombucha Mule; lime squeezes for Tang Dynasty. | E12: Amazon / Restaurant Supply
A13: ☐ | B13: Cutting board | C13: 2 | D13: Garnish prep: citrus wheels, apple/pear, cucumber, candied ginger, mint sprigs. | E13: Camp kitchen (check first)
A14: ☐ | B14: Paring knife | C14: 2 | D14: Same garnish prep as cutting board. | E14: Camp kitchen (check first)
A15: ☐ | B15: Fine mesh strainer | C15: 1 | D15: Strain muddled mint/pulp when pouring Watermelon Mint Lemonade and Kombucha Mule. | E15: Amazon / Restaurant Supply
A16: ☐ | B16: Rimming plate / shallow dish | C16: 1 | D16: Tajín rim for A Ginger's Pickle. | E16: Amazon / Restaurant Supply
... A24: ☐ | B24: Food-safe container, 1 gallon (sealed) | C24: 2 | D24: Mixing and holding lemonade from concentrate — ~3.4 gal for the week (Watermelon Sugar High + Tue Smoke Test + Sat Blue Screen), batched in two sessions instead of daily. Doubles as reserve capacity for the Wednesday 3-jug batch. | E24: Amazon / Restaurant Supply

Sheet Daily Schedule
A1: Daily Special Offerings — Sunday to Friday (one 10 L jug per night; Saturday is a built drink)
A2: One 10 L drink-dispenser batch (~33 × ~10 oz servings) per night Sun-Fri (Wednesday is a 3-jug batch — see row 7), batched NON-alcoholic: decant ~2L pitchers into a punch bowl for self-serve, refill from the jug as needed; 1.5 oz liquor added per cup on request for those who want it. Michelada is no longer tracked here — it's built to order from whichever keg is on the beer line (see Keg Rotation tab). LIQUOR COLUMNS: column P is the liquor the model actually sizes and buys (column R = oz needed). Column Q is a SIGNAGE-ONLY second option — it is deliberately excluded from every calculation, so adding or changing it never moves a bottle count. Both bottles are already on the shopping list either way; the jug's liquor allocation is shared between whichever one the guest picks.
A3: Day | B3: Slot | C3: Offering | D3: Format | E3: Servings | F3: Ingredient 1 | G3: Ing 1 oz | H3: Ingredient 2 | I3: Ing 2 oz | J3: Ingredient 3 | K3: Ing 3 oz | L3: Ingredient 4 | M3: Ing 4 oz | N3: Ingredient 5 | O3: Ing 5 oz | P3: Alcohol (optional) | Q3: Alcohol — 2nd option (SIGNAGE ONLY) | R3: Alcohol oz needed | S3: Notes
A4: Sunday | B4: 1 | C4: Cherry Bomb (Cherry Limeade) | D4: 10 L jug | E4: =Assumptions!$B$117 | F4: Sprite | G4: =E4*2.5 | H4: Cherry syrup | I4: =E4*0.75 | J4: Lime juice (bottled) | K4: =E4*1 | L4: Maraschino cherries (garnish) | M4: 0 | N4: Soda water | O4: =E4*1 | P4: Vodka | Q4: Blanco Tequila | R4: =E4*Assumptions!$B$39*Assumptions!$B$40 | S4: Sonic-style cherry limeade, moved off Wednesday to open the arrival party. Sprite cut from 6oz to 3oz and now to 2.5oz, with 1oz of soda water added alongside it (1 : 2.5 soda water to Sprite) — the cherry + lime carry the flavour, so the soda water lengthens the drink without watering down the taste the way plain fill does. Still topped with water/ice to fill the 10 L jug; the fill just shrinks by half an ounce per serving.
A5: Monday | B5: 1 | C5: Hard Reset (Watermelon-Mint Aqua Fresca) | D5: 10 L jug | E5: =Assumptions!$B$117 | F5: Watermelon (fresh, blended) | G5: =E5*Assumptions!$B$51 | H5: Agave syrup | I5: =E5*Assumptions!$B$54 | J5: Fresh mint (blended) | K5: 5 | L5: Fresh lime (squeeze) | M5: 0 | N5: Water (fill) | O5: 0 | P5: Blanco Tequila | Q5: Vodka | R5: =E5*Assumptions!$B$39*Assumptions!$B$40 | S5: Blend melon chunks with a handful of mint, strain rough, add agave + lime, top with STILL water to fill the jug (traditional fresca — skip tonic; optional soda-water splash per cup for fizz). ~1-2 melons per batch; melons travel fine unrefrigerated. Optional Blanco Tequila per cup makes it a watermelon margarita — melon, mint and lime are already the whole drink.
A6: Tuesday | B6: 1 | C6: Smoke Test (Lapsang Souchong Lemonade) | D6: 10 L jug | E6: =Assumptions!$B$117 | F6: Lapsang souchong | G6: =E6*Assumptions!$B$142 | H6: Lemonade | I6: =E6*3 | J6: Lime juice (bottled) | K6: =E6*0.5 | L6: Water/ice (fill) | M6: 0 | O6: 0 | P6: Whiskey | Q6: Spiced Rum | R6: =E6*Assumptions!$B$39*Assumptions!$B$40 | S6: Cold-steep ~2 oz of lapsang leaf overnight (or steep hot and chill) to make ~1.3 gal of STRONG smoky tea, then build the jug: 5 oz strong tea + 3 oz lemonade + 0.5 oz lime per serving, topped with water/ice. ~1.5 tsp salt per jug. Naturally still, so nothing to go flat. WARNING: lapsang runs from 'campfire' to 'ashtray' fast — brew it weaker than you think and taste before committing the jug. Optional Whiskey leans into the smoke.
A7: Wednesday | B7: 1 | C7: Red Flag (Agua de Jamaica) | D7: 3 x 10 L jugs | E7: =Assumptions!$B$117*3 | F7: Dried hibiscus | G7: =E7*Assumptions!$B$124 | H7: Agave syrup | I7: =E7*0.35 | J7: Lime juice (bottled) | K7: =E7*0.5 | L7: Water (fill) | M7: 0 | O7: 0 | P7: Blanco Tequila | Q7: Spiced Rum | R7: =E7*Assumptions!$B$39*Assumptions!$B$40 | S7: Hibiscus agua fresca — steep ~2.8 oz dried flowers in hot water, strain, cool, then sweeten with agave and fill the jug with cold water/ice. Cold-steeping overnight works too. Deep magenta, properly tart, naturally still so there is nothing to go flat. ~1.5 tsp salt per jug. NOTE: hibiscus stains — cups, hands, clothing. Optional Blanco Tequila makes it a jamaica margarita. WEDNESDAY IS A TRIPLE BATCH (3 jugs, 99 servings) — hosting overflow from the party next door. Steep ~3x the hibiscus (still one lb bag) and scale agave and lime with it; the per-serving amounts are unchanged, only the batch count. Batch all three ahead of the door opening — hibiscus needs steep-and-cool time and you will not catch up mid-rush.
A8: Thursday | B8: 1 | C8: Gradient Descent (Malibu Sunrise) | D8: 10 L jug | E8: =Assumptions!$B$117 | F8: Orange juice | G8: =E8*4 | H8: Pineapple juice | I8: =E8*3 | J8: Grenadine | K8: =E8*0.5 | L8: Lime juice (bottled) | M8: =E8*0.5 | N8: Passion fruit purée | O8: =E8*0.5 | P8: Coconut Rum | Q8: Spiced Rum | R8: =E8*Assumptions!$B$39*Assumptions!$B$40 | S8: Batch OJ + pineapple + passion fruit + lime in the jug, then top with water/ice — juice cut from 9oz to 7oz per serving so it is not pure sugar in the heat. Add the grenadine to each CUP (it sinks) for the sunrise gradient. ~1.5 tsp salt per jug. Optional Malibu per cup. Orange slice / cherry garnish if supplies allow.
A9: Friday | B9: 1 | C9: Whore-chata | D9: 10 L jug | E9: =Assumptions!$B$117 | F9: Horchata mix | G9: =E9*3 | H9: Coconut cream | I9: =E9*0.5 | J9: Water/ice (fill) | K9: 0 | L9: Vanilla syrup | M9: =E9*0.25 | P9: Spiced Rum | Q9: Bourbon | R9: =E9*Assumptions!$B$39*Assumptions!$B$40 | S9: Rice-milk base + cinnamon/vanilla syrup, batched cold; optional Spiced Rum float. Coconut cream instead of dairy — nothing on the menu needs refrigeration now.
A10: Saturday | B10: 1 | C10: Blue Screen of Death (DIY Baja Blast) | D10: 10 L jug | E10: =Assumptions!$B$117 | F10: Lemonade | G10: =E10*4 | H10: Lime juice (bottled) | I10: =E10*1 | J10: Blue spirulina | K10: 0 | L10: Water/ice (fill) | M10: 0 | N10: Mountain Dew | O10: =E10*3 | P10: Blanco Tequila | Q10: Vodka | R10: =E10*Assumptions!$B$39*Assumptions!$B$40 | S10: BUILT PER CUP — the jug holds only the blue base (lemonade + lime + water, tinted teal with ~1-2 tsp blue spirulina). Top each cup with 3 oz of COLD Mountain Dew from a can at serve time. That is the only way this still has carbonation at hour six. Lime is what makes it read as Baja Blast. ~1.5 tsp salt per jug. Stir the jug now and then — spirulina settles. Optional Blanco Tequila for a Baja-rita.
A11: Sunday | C11: Turtle Soup (Mix of leftover alcohol) | S11: This is JUST for signage purposes, it will be made from whatever is left over.
A12: BACKUP | C12: Salted Limeade (spare jug — no extra shopping) | D12: 10 L jug | S12: Fallback if a night runs dry or we want a 7th jug: lime juice 1oz + agave 0.5oz + water/ice to fill + ~1.5 tsp salt per jug. Deliberately left at 0 servings so it buys nothing — by the back half of the week we will already have the lime, syrup and salt on hand. Give it a serving count only if we decide to actually run it.
C13: Sakura Kisses (Described in Built Drinks)
A17: INGREDIENT TOTALS (jug-batch buys) | B17: Total oz | C17: +buffer | D17: Units to buy | E17: $/unit | F17: Subtotal | G17: Note
A18: Watermelon (whole melons) | B18: =SUMPRODUCT(('Daily Schedule'!$F$4:$F$15="Watermelon (fresh, blended)")*'Daily Schedule'!$G$4:$G$15)+SUMPRODUCT(('Daily Schedule'!$H$4:$H$15="Watermelon (fresh, blended)")*'Daily Schedule'!$I$4:$I$15)+SUMPRODUCT(('Daily Schedule'!$J$4:$J$15="Watermelon (fresh, blended)")*'Daily Schedule'!$K$4:$K$15)+SUMPRODUCT(('Daily Schedule'!$L$4:$L$15="Watermelon (fresh, blended)")*'Daily Schedule'!$M$4:$M$15)+SUMPRODUCT(('Daily Schedule'!$N$4:$N$15="Watermelon (fresh, blended)")*'Daily Schedule'!$O$4:$O$15) | C18: =B18*(1+Assumptions!$B$5) | D18: =CEILING(C18/Assumptions!$B$76,1) | E18: =Assumptions!$B$77 | F18: =D18*E18 | G18: Mon fresca — blend & strain
A19: Agave syrup (bottles) | B19: =SUMPRODUCT(('Daily Schedule'!$F$4:$F$15="Agave syrup")*'Daily Schedule'!$G$4:$G$15)+SUMPRODUCT(('Daily Schedule'!$H$4:$H$15="Agave syrup")*'Daily Schedule'!$I$4:$I$15)+SUMPRODUCT(('Daily Schedule'!$J$4:$J$15="Agave syrup")*'Daily Schedule'!$K$4:$K$15)+SUMPRODUCT(('Daily Schedule'!$L$4:$L$15="Agave syrup")*'Daily Schedule'!$M$4:$M$15)+SUMPRODUCT(('Daily Schedule'!$N$4:$N$15="Agave syrup")*'Daily Schedule'!$O$4:$O$15) | C19: =B19*(1+Assumptions!$B$5) | D19: =CEILING(C19/Assumptions!$B$132,1) | E19: =Assumptions!$B$133 | F19: =D19*E19 | G19: Mon fresca + Wed Red Flag
A20: TAB TOTAL (rows above + below) | F20: =F18+F19+SUM(F23:F30)
A21: Jug-format servings (for total-servings calc) | B21: =SUM(E4:E15)
A22: New special ingredients (Sun punch / Tue Baja Blast / Thu sunrise):
A23: Orange juice (64oz cartons) | B23: =SUMPRODUCT(('Daily Schedule'!$F$4:$F$15="Orange juice")*'Daily Schedule'!$G$4:$G$15)+SUMPRODUCT(('Daily Schedule'!$H$4:$H$15="Orange juice")*'Daily Schedule'!$I$4:$I$15)+SUMPRODUCT(('Daily Schedule'!$J$4:$J$15="Orange juice")*'Daily Schedule'!$K$4:$K$15)+SUMPRODUCT(('Daily Schedule'!$L$4:$L$15="Orange juice")*'Daily Schedule'!$M$4:$M$15)+SUMPRODUCT(('Daily Schedule'!$N$4:$N$15="Orange juice")*'Daily Schedule'!$O$4:$O$15) | C23: =B23*(1+Assumptions!$B$5) | D23: =CEILING(C23/Assumptions!$B$69,1) | E23: =Assumptions!$B$70 | F23: =D23*E23 | G23: Thu sunrise + Sat fresca
A24: Pineapple juice (46oz cans) | B24: =SUMPRODUCT(('Daily Schedule'!$F$4:$F$15="Pineapple juice")*'Daily Schedule'!$G$4:$G$15)+SUMPRODUCT(('Daily Schedule'!$H$4:$H$15="Pineapple juice")*'Daily Schedule'!$I$4:$I$15)+SUMPRODUCT(('Daily Schedule'!$J$4:$J$15="Pineapple juice")*'Daily Schedule'!$K$4:$K$15)+SUMPRODUCT(('Daily Schedule'!$L$4:$L$15="Pineapple juice")*'Daily Schedule'!$M$4:$M$15)+SUMPRODUCT(('Daily Schedule'!$N$4:$N$15="Pineapple juice")*'Daily Schedule'!$O$4:$O$15) | C24: =B24*(1+Assumptions!$B$5) | D24: =CEILING(C24/Assumptions!$B$71,1) | E24: =Assumptions!$B$72 | F24: =D24*E24 | G24: Thu sunrise
A25: Grenadine (bottles) | B25: =SUMPRODUCT(('Daily Schedule'!$F$4:$F$15="Grenadine")*'Daily Schedule'!$G$4:$G$15)+SUMPRODUCT(('Daily Schedule'!$H$4:$H$15="Grenadine")*'Daily Schedule'!$I$4:$I$15)+SUMPRODUCT(('Daily Schedule'!$J$4:$J$15="Grenadine")*'Daily Schedule'!$K$4:$K$15)+SUMPRODUCT(('Daily Schedule'!$L$4:$L$15="Grenadine")*'Daily Schedule'!$M$4:$M$15)+SUMPRODUCT(('Daily Schedule'!$N$4:$N$15="Grenadine")*'Daily Schedule'!$O$4:$O$15) | C25: =B25*(1+Assumptions!$B$5) | D25: =CEILING(C25/Assumptions!$B$73,1) | E25: =Assumptions!$B$74 | F25: =D25*E25 | G25: Sun punch + Thu sunrise
A26: Blue spirulina (jar) | D26: 1 | E26: =Assumptions!$B$75 | F26: =D26*E26 | G26: Grams not oz — ~1-2 tsp per 4-gal batch; one jar covers the week
A27: Lime juice (48oz bottles) | B27: =SUMPRODUCT(('Daily Schedule'!$F$4:$F$15="Lime juice (bottled)")*'Daily Schedule'!$G$4:$G$15)+SUMPRODUCT(('Daily Schedule'!$H$4:$H$15="Lime juice (bottled)")*'Daily Schedule'!$I$4:$I$15)+SUMPRODUCT(('Daily Schedule'!$J$4:$J$15="Lime juice (bottled)")*'Daily Schedule'!$K$4:$K$15)+SUMPRODUCT(('Daily Schedule'!$L$4:$L$15="Lime juice (bottled)")*'Daily Schedule'!$M$4:$M$15)+SUMPRODUCT(('Daily Schedule'!$N$4:$N$15="Lime juice (bottled)")*'Daily Schedule'!$O$4:$O$15)+SUMPRODUCT((Recipes!$H$3:$H$18="Lime juice (bottled)")*Recipes!$I$3:$I$18*Recipes!$B$3:$B$18) | C27: =B27*(1+Assumptions!$B$5) | D27: =CEILING(C27/Assumptions!$B$78,1) | E27: =Assumptions!$B$79 | F27: =D27*E27 | G27: Wed Cherry Limeade
A28: Maraschino cherries (jars) | D28: 2 | E28: =Assumptions!$B$80 | F28: =D28*E28 | G28: One cherry + juice splash per Wed cup (~35-40 cherries)
A29: Dried hibiscus (lb bags) | B29: =SUMPRODUCT(('Daily Schedule'!$F$4:$F$15="Dried hibiscus")*'Daily Schedule'!$G$4:$G$15)+SUMPRODUCT(('Daily Schedule'!$H$4:$H$15="Dried hibiscus")*'Daily Schedule'!$I$4:$I$15)+SUMPRODUCT(('Daily Schedule'!$J$4:$J$15="Dried hibiscus")*'Daily Schedule'!$K$4:$K$15)+SUMPRODUCT(('Daily Schedule'!$L$4:$L$15="Dried hibiscus")*'Daily Schedule'!$M$4:$M$15)+SUMPRODUCT(('Daily Schedule'!$N$4:$N$15="Dried hibiscus")*'Daily Schedule'!$O$4:$O$15) | C29: =B29*(1+Assumptions!$B$5) | D29: =CEILING(C29/Assumptions!$B$125,1) | E29: =Assumptions!$B$126 | F29: Kombucha | G29: Wed Red Flag — packs tiny and shelf-stable
A30: Lapsang souchong (loose leaf) | B30: =SUMPRODUCT(('Daily Schedule'!$F$4:$F$15="Lapsang souchong")*'Daily Schedule'!$G$4:$G$15)+SUMPRODUCT(('Daily Schedule'!$H$4:$H$15="Lapsang souchong")*'Daily Schedule'!$I$4:$I$15)+SUMPRODUCT(('Daily Schedule'!$J$4:$J$15="Lapsang souchong")*'Daily Schedule'!$K$4:$K$15)+SUMPRODUCT(('Daily Schedule'!$L$4:$L$15="Lapsang souchong")*'Daily Schedule'!$M$4:$M$15)+SUMPRODUCT(('Daily Schedule'!$N$4:$N$15="Lapsang souchong")*'Daily Schedule'!$O$4:$O$15) | C30: =B30*(1+Assumptions!$B$5) | D30: =CEILING(C30/Assumptions!$B$143,1) | E30: =Assumptions!$B$144 | F30: =D30*E30 | G30: Tue Smoke Test — packs to nothing

Sheet Keg Rotation
A1: Keg Rotation — two continuous tap lines (Sunday party runs the two easiest kegs; 1 jug special every night on the Daily Schedule tab)
A2: We always have exactly two taps live: a 'beer line' that evolves Paloma -> Mexican Lager (Michelada) -> Blonde Ale, and an 'other tap' line that runs Cider (Sun-Mon) -> Kombucha (Tue-Fri, both kegs) -> Green Tea (Sat). Sunday's party opens on Paloma + Cider for the fastest possible setup.
A4: Day | B4: Beer Line | C4: Other Line | D4: Notes
A5: Sunday (party) | B5: Ancho Paloma Sour Ale | C5: Cider | D5: Arrival party, minimal setup time — Paloma + Cider, both served straight.
A6: Monday | B6: Ancho Paloma Sour Ale | C6: Cider | D6: Beer line opens on Paloma; other line opens on Cider.
A7: Tuesday | B7: Ancho Paloma Sour Ale | C7: Kombucha – Clear Mind | D7: Other line swaps to Kombucha (keg 1); Paloma's last day on the beer line.
A8: Wednesday | B8: Mexican Lager (Michelada) | C8: Kombucha – Clear Mind | D8: Beer line swaps to Mexican Lager, built into Michelada; Kombucha continues.
A9: Thursday | B9: Mexican Lager (Michelada) | C9: Kombucha – Passion Fruit | D9: Continues.
A10: Friday | B10: Biggest Little Blonde Ale | C10: Kombucha – Passion Fruit | D10: Beer line closes on the Blonde Ale; Kombucha rolls onto keg 2 on the other line.
A11: Saturday | B11: Biggest Little Blonde Ale | C11: Green Tea | D11: Catboy Café finale — other line swaps to Green Tea with the sakura+orange syrup add-on.
